Workbook

Sheet Notes
A1: Notes for Analysis\

Sheet Scaler
A1: run | B1: ts | C1: ppac | D1: ppac_rate | E1: f2pl | F1: f2pl_rate | G1: f3pl | H1: f3pl_rate | I1: hwtriga | J1: hwtriga_rate | K1: hwtrigb | L1: hwtrigb_rate | M1: refp | N1: refp_rate | O1: reft | P1: reft_rate | Q1: livetime
A2: 223 | B2: 555.96592 | C2: 1722301 | D2: 3097.8535 | E2: 20 | F2: 0.035973428 | G2: 617 | H2: 1.1097802 | I2: 2737 | J2: 4.9229636 | K2: 2820 | L2: 5.0722533 | M2: 0 | N2: 0 | O2: 556 | P2: 1.0000613 | Q2: =I2/K2 -> 0.97056738
A3: 224 | B3: 444.45302 | C3: 1397599 | D3: 3144.537 | E3: 20 | F3: 0.044999131 | G3: 501 | H3: 1.1272282 | I3: 2154 | J3: 4.8464064 | K3: 2232 | L3: 5.0219031 | M3: 0 | N3: 0 | O3: 444 | P3: 0.99898072 | Q3: =I3/K3 -> 0.96505376
A4: 225 | B4: 51.908804 | C4: 145403 | D4: 2801.124 | E4: 2 | F4: 0.038529109 | G4: 46 | H4: 0.88616952 | I4: 230 | J4: 4.4308476 | K4: 234 | L4: 4.5079058 | M4: 0 | N4: 0 | O4: 52 | P4: 1.0017568 | Q4: =I4/K4 -> 0.98290598
A5: 226 | B5: 1001.9243 | C5: 3235930 | D5: 3229.7151 | E5: 32 | F5: 0.031938541 | G5: 1093 | H5: 1.0909008 | I5: 4973 | J5: 4.9634488 | K5: 5155 | L5: 5.1450993 | M5: 0 | N5: 0 | O5: 1002 | P5: 1.0000756 | Q5: =I5/K5 -> 0.96469447
A6: 251 | B6: 171.64482 | C6: 215518 | D6: 1255.6044 | E6: 4 | F6: 0.02330394 | G6: 394 | H6: 2.2954377 | I6: 1532 | J6: 8.9254075 | K6: 1618 | L6: 9.4264421 | M6: 0 | N6: 0 | O6: 171 | P6: 0.99624326 | Q6: =I6/K6 -> 0.94684796
A7: 252 | B7: 964.12724 | C7: 1135702 | D7: 1177.9586 | E7: 30 | F7: 0.03111622 | G7: 1948 | H7: 2.0204802 | I7: 7738 | J7: 8.0259116 | K7: 8175 | L7: 8.4791713 | M7: 0 | N7: 0 | O7: 964 | P7: 0.99986802 | Q7: =I7/K7 -> 0.94654434
A8: 253 | B8: 581.73708 | C8: 699110 | D8: 1201.7628 | E8: 20 | F8: 0.03437979 | G8: 1213 | H8: 2.0851344 | I8: 4918 | J8: 8.453991 | K8: 5162 | L8: 8.8734244 | M8: 0 | N8: 0 | O8: 582 | P8: 1.000452 | Q8: =I8/K8 -> 0.9527315
A9: 254 | B9: 905.69925 | C9: 1268858 | D9: 1400.9706 | E9: 26 | F9: 0.0287071 | G9: 2029 | H9: 2.240258 | I9: 8468 | J9: 9.349682 | K9: 8965 | L9: 9.8984293 | M9: 0 | N9: 0 | O9: 905 | P9: 0.99922794 | Q9: =I9/K9 -> 0.94456219
A10: 259 | B10: 383.49036 | C10: 201055 | D10: 524.27655 | E10: 6 | F10: 0.01564576 | G10: 380 | H10: 0.99089845 | I10: 1414 | J10: 3.6871853 | K10: 1450 | L10: 3.7810599 | M10: 0 | N10: 0 | O10: 384 | P10: 1.001329 | Q10: =I10/K10 -> 0.97517241
A11: 260 | B11: 711.22968 | C11: 371380 | D11: 522.16606 | E11: 28 | F11: 0.03936844 | G11: 607 | H11: 0.85345145 | I11: 2492 | J11: 3.5037908 | K11: 2537 | L11: 3.5670615 | M11: 0 | N11: 0 | O11: 711 | P11: 0.99967706 | Q11: =I11/K11 -> 0.98226251
A12: 261 | B12: 1198.7236 | C12: 603245 | D12: 503.23943 | E12: 38 | F12: 0.03170038 | G12: 1047 | H12: 0.87342901 | I12: 4310 | J12: 3.595491 | K12: 4397 | L12: 3.6680682 | M12: 0 | N12: 0 | O12: 1199 | P12: 1.0002305 | Q12: =I12/K12 -> 0.98021378
A13: 262 | B13: 506.83714 | C13: 265263 | D13: 523.36931 | E13: 12 | F13: 0.02367624 | G13: 488 | H13: 0.96283394 | I13: 1801 | J13: 3.5534097 | K13: 1840 | L13: 3.6303575 | M13: 0 | N13: 0 | O13: 507 | P13: 1.0003213 | Q13: =I13/K13 -> 0.97880435
... A272: 789 | B272: 386.28727 | C272: 9639440 | D272: 24954.071 | E272: 4291619977 | F272: 11109918 | G272: 2438 | H272: 6.3113652 | I272: 2241 | J272: 5.801382 | K272: 2320 | L272: 6.005893 | M272: 1 | N272: 0.00258875 | O272: 386 | P272: 0.99925634 | Q272: =I272/K272 -> 0.96594828

Sheet RunTime
A1: Run | B1: start_time | C1: stop_time | D1: LEBT_mean (mA) | E1: LEBT_integral (mA x sec) | F1: LEBT_std (mA) | G1: LEBT_integral_std (mA x sec) | H1: time_difference | I1: diff_with_ts | J1: LEBT_integral_ts (mA x sec) | K1: LEBT_integral_ts_1K
A2: 1 | B2: 45482.415 | C2: 45482.422 | D2: 4.4065642e-05 | E2: 0.026571582 | F2: 2.4117439e-08 | G2: 1.4542816e-05 | H2: =(C2-B2)*1440*60 -> 603 | I2: =IFNA(VLOOKUP(A2,표2[#ALL],2, FALSE), "") | J2: =IF(I2 ="","",D2*I2) | K2: =IF(J2="","",J2*$L$14)
A3: 2 | B3: 45482.422 | C3: 45482.427 | D3: 4.2894591e-05 | E3: 0.016557312 | F3: 3.1739872e-07 | G3: 0.00012251591 | H3: =(C3-B3)*1440*60 -> 386 | I3: =IFNA(VLOOKUP(A3,표2[#ALL],2, FALSE), "") | J3: =IF(I3 ="","",D3*I3) | K3: =IF(J3="","",J3*$L$14)
A4: 3 | B4: 45482.428 | C4: 45482.437 | D4: 4.2527418e-05 | E4: 0.031427762 | F4: 2.3982546e-07 | G4: 0.00017723101 | H4: =(C4-B4)*1440*60 -> 739 | I4: =IFNA(VLOOKUP(A4,표2[#ALL],2, FALSE), "") | J4: =IF(I4 ="","",D4*I4) | K4: =IF(J4="","",J4*$L$14)
A5: 4 | B5: 45482.438 | C5: 45482.455 | D5: 4.2959897e-05 | E5: 0.063881366 | F5: 9.0022661e-08 | G5: 0.0001338637 | H5: =(C5-B5)*1440*60 -> 1487 | I5: =IFNA(VLOOKUP(A5,표2[#ALL],2, FALSE), "") | J5: =IF(I5 ="","",D5*I5) | K5: =IF(J5="","",J5*$L$14)
A6: 6 | B6: 45482.457 | C6: 45482.46 | D6: 4.3064644e-05 | E6: 0.0089143814 | F6: 3.6972157e-08 | G6: 7.6532366e-06 | H6: =(C6-B6)*1440*60 -> 207 | I6: =IFNA(VLOOKUP(A6,표2[#ALL],2, FALSE), "") | J6: =IF(I6 ="","",D6*I6) | K6: =IF(J6="","",J6*$L$14)
A7: 7 | B7: 45482.461 | C7: 45482.462 | D7: 4.0674799e-05 | E7: 0.0054504231 | F7: 8.2756278e-07 | G7: 0.00011089341 | H7: =(C7-B7)*1440*60 -> 134 | I7: =IFNA(VLOOKUP(A7,표2[#ALL],2, FALSE), "") | J7: =IF(I7 ="","",D7*I7) | K7: =IF(J7="","",J7*$L$14)
A8: 8 | B8: 45482.464 | C8: 45482.47 | D8: 4.1979452e-05 | E8: 0.022459007 | F8: 2.505934e-07 | G8: 0.00013406747 | H8: =(C8-B8)*1440*60 -> 535 | I8: =IFNA(VLOOKUP(A8,표2[#ALL],2, FALSE), "") | J8: =IF(I8 ="","",D8*I8) | K8: =IF(J8="","",J8*$L$14)
A9: 9 | B9: 45482.473 | C9: 45482.478 | D9: 4.1817419e-05 | E9: 0.018943291 | F9: 2.8244537e-07 | G9: 0.00012794775 | H9: =(C9-B9)*1440*60 -> 453 | I9: =IFNA(VLOOKUP(A9,표2[#ALL],2, FALSE), "") | J9: =IF(I9 ="","",D9*I9) | K9: =IF(J9="","",J9*$L$14)
A10: 10 | B10: 45482.479 | C10: 45482.479 | D10: 1.9413689e-05 | E10: 0.00031061902 | F10: 5.4000614e-06 | G10: 8.6400983e-05 | H10: =(C10-B10)*1440*60 -> 16 | I10: =IFNA(VLOOKUP(A10,표2[#ALL],2, FALSE), "") | J10: =IF(I10 ="","",D10*I10) | K10: =IF(J10="","",J10*$L$14)
A11: 11 | B11: 45482.481 | C11: 45482.484 | D11: 4.1196446e-05 | E11: 0.01124663 | F11: 4.6159255e-07 | G11: 0.00012601477 | H11: =(C11-B11)*1440*60 -> 273 | I11: =IFNA(VLOOKUP(A11,표2[#ALL],2, FALSE), "") | J11: =IF(I11 ="","",D11*I11) | K11: =IF(J11="","",J11*$L$14)
A12: 12 | B12: 45482.484 | C12: 45482.484 | D12: 6.5228419e-06 | E12: 0.00010436547 | F12: 4.0388496e-06 | G12: 6.4621594e-05 | H12: =(C12-B12)*1440*60 -> 16 | I12: =IFNA(VLOOKUP(A12,표2[#ALL],2, FALSE), "") | J12: =IF(I12 ="","",D12*I12) | K12: =IF(J12="","",J12*$L$14)
A13: 13 | B13: 45482.485 | C13: 45482.485 | D13: 3.2427276e-05 | E13: 0.0012970911 | F13: 2.8975571e-06 | G13: 0.00011590229 | H13: =(C13-B13)*1440*60 -> 40 | I13: =IFNA(VLOOKUP(A13,표2[#ALL],2, FALSE), "") | J13: =IF(I13 ="","",D13*I13) | K13: =IF(J13="","",J13*$L$14) | L13: 1K_!M _Conv | M13: error
A14: 14 | B14: 45482.486 | C14: 45482.49 | D14: 4.2616516e-05 | E14: 0.013978217 | F14: 2.7804415e-08 | G14: 9.1198481e-06 | H14: =(C14-B14)*1440*60 -> 328 | I14: =IFNA(VLOOKUP(A14,표2[#ALL],2, FALSE), "") | J14: =IF(I14 ="","",D14*I14) | K14: =IF(J14="","",J14*$L$14) | L14: 0.8241 | M14: 0.0135
A15: 15 | B15: 45482.491 | C15: 45482.495 | D15: 4.2431653e-05 | E15: 0.013917582 | F15: 2.9181945e-08 | G15: 9.5716779e-06 | H15: =(C15-B15)*1440*60 -> 328 | I15: =IFNA(VLOOKUP(A15,표2[#ALL],2, FALSE), "") | J15: =IF(I15 ="","",D15*I15) | K15: =IF(J15="","",J15*$L$14)
A16: 16 | B16: 45482.497 | C16: 45482.497 | D16: 4.2317132e-05 | E16: 0.001904271 | F16: 6.6722785e-08 | G16: 3.0025253e-06 | H16: =(C16-B16)*1440*60 -> 45 | I16: =IFNA(VLOOKUP(A16,표2[#ALL],2, FALSE), "") | J16: =IF(I16 ="","",D16*I16) | K16: =IF(J16="","",J16*$L$14)
A17: 17 | B17: 45482.498 | C17: 45482.5 | D17: 1.9020009e-05 | E17: 0.0037279218 | F17: 1.5410136e-06 | G17: 0.00030203867 | H17: =(C17-B17)*1440*60 -> 196 | I17: =IFNA(VLOOKUP(A17,표2[#ALL],2, FALSE), "") | J17: =IF(I17 ="","",D17*I17) | K17: =IF(J17="","",J17*$L$14)
A18: 18 | B18: 45482.502 | C18: 45482.505 | D18: 4.2343427e-05 | E18: 0.014312078 | F18: 2.6233109e-08 | G18: 8.8667909e-06 | H18: =(C18-B18)*1440*60 -> 338 | I18: =IFNA(VLOOKUP(A18,표2[#ALL],2, FALSE), "") | J18: =IF(I18 ="","",D18*I18) | K18: =IF(J18="","",J18*$L$14)
A19: 19 | B19: 45482.506 | C19: 45482.507 | D19: 3.701264e-05 | E19: 0.0031090618 | F19: 1.568858e-06 | G19: 0.00013178407 | H19: =(C19-B19)*1440*60 -> 84 | I19: =IFNA(VLOOKUP(A19,표2[#ALL],2, FALSE), "") | J19: =IF(I19 ="","",D19*I19) | K19: =IF(J19="","",J19*$L$14)
A20: 20 | B20: 45482.508 | C20: 45482.509 | D20: 4.2215097e-05 | E20: 0.0034194228 | F20: 5.1430821e-08 | G20: 4.1658965e-06 | H20: =(C20-B20)*1440*60 -> 81 | I20: =IFNA(VLOOKUP(A20,표2[#ALL],2, FALSE), "") | J20: =IF(I20 ="","",D20*I20) | K20: =IF(J20="","",J20*$L$14)
A21: 21 | B21: 45482.51 | C21: 45482.513 | D21: 4.2132135e-05 | E21: 0.011375676 | F21: 2.8459885e-08 | G21: 7.684169e-06 | H21: =(C21-B21)*1440*60 -> 270 | I21: =IFNA(VLOOKUP(A21,표2[#ALL],2, FALSE), "") | J21: =IF(I21 ="","",D21*I21) | K21: =IF(J21="","",J21*$L$14)
A22: 22 | B22: 45482.513 | C22: 45482.515 | D22: 4.2145044e-05 | E22: 0.0059003062 | F22: 4.0181847e-08 | G22: 5.6254585e-06 | H22: =(C22-B22)*1440*60 -> 140 | I22: =IFNA(VLOOKUP(A22,표2[#ALL],2, FALSE), "") | J22: =IF(I22 ="","",D22*I22) | K22: =IF(J22="","",J22*$L$14)
A23: 23 | B23: 45482.517 | C23: 45482.519 | D23: 4.2308229e-05 | E23: 0.0084616458 | F23: 3.3497298e-08 | G23: 6.6994596e-06 | H23: =(C23-B23)*1440*60 -> 200 | I23: =IFNA(VLOOKUP(A23,표2[#ALL],2, FALSE), "") | J23: =IF(I23 ="","",D23*I23) | K23: =IF(J23="","",J23*$L$14)
A24: 24 | B24: 45482.521 | C24: 45482.522 | D24: 4.2113381e-05 | E24: 0.0033690705 | F24: 5.8288984e-08 | G24: 4.6631188e-06 | H24: =(C24-B24)*1440*60 -> 80 | I24: =IFNA(VLOOKUP(A24,표2[#ALL],2, FALSE), "") | J24: =IF(I24 ="","",D24*I24) | K24: =IF(J24="","",J24*$L$14)
A25: 25 | B25: 45482.523 | C25: 45482.524 | D25: 4.1998118e-05 | E25: 0.0026878795 | F25: 6.0028174e-08 | G25: 3.8418031e-06 | H25: =(C25-B25)*1440*60 -> 64 | I25: =IFNA(VLOOKUP(A25,표2[#ALL],2, FALSE), "") | J25: =IF(I25 ="","",D25*I25) | K25: =IF(J25="","",J25*$L$14)
A26: 26 | B26: 45482.524 | C26: 45482.525 | D26: 2.7487507e-05 | E26: 0.0011544753 | F26: 3.1667226e-06 | G26: 0.00013300235 | H26: =(C26-B26)*1440*60 -> 42 | I26: =IFNA(VLOOKUP(A26,표2[#ALL],2, FALSE), "") | J26: =IF(I26 ="","",D26*I26) | K26: =IF(J26="","",J26*$L$14)
... A678: 789 | B678: 45527.745 | C678: 45527.75 | D678: 3.418648e-05 | E678: 0.013777152 | F678: 2.1268955e-07 | G678: 8.571389e-05 | H678: =(C678-B678)*1440*60 -> 403 | I678: =IFNA(VLOOKUP(A678,표2[#ALL],2, FALSE), "") -> 386.28727 | J678: =IF(I678 ="","",D678*I678) -> 0.013205802 | K678: =IF(J678="","",J678*$L$14) -> 0.010882901

Sheet F0
A1: 일자 | B1: 시간 | C1: Ratio (%) | D1: Run0 | E1: Run1 | F1: 메모
A2: 45853 | B2: 0.72986111 | C2: 0.919 | F2: 2025.07.15이라고 되어있지만, 16일 빔정보 들어가있음
A3: 45854 | B3: 0.72986111 | C3: 0.919 | D3: 220 | E3: 222
A4: 45855 | B4: 0.41041667 | C4: 0.895 | D4: 223 | E4: 268
A5: 45856 | B5: 0.4125 | C5: 0.94 | D5: 269 | E5: 322
A6: 45860 | B6: 0.46319444 | C6: 0.945 | D6: 363 | E6: 432
A7: 45861 | B7: 0.68888889 | C7: 0.804 | D7: 433 | E7: 440
A8: 45881 | B8: 0.67083333 | C8: 0.783 | D8: 524 | E8: 581 | F8: 10:00, 14:34경 사진이 있으나 16:06과 비슷한 분포로 같이 취급
A9: 45882 | B9: 0.67083333 | C9: 0.783 | D9: 582 | E9: 675 | F9: 8.13 10:22경 분포, 8.14 10:04경의 분포가 8.12 16:06와 비슷하여 이것으로 진행
A10: 45883 | B10: 0.70486111 | C10: 0.798 | D10: 700 | E10: 789 | F10: 8.22, 8.23 데이터는 모두 8.14 저녁 분포와 비슷한 것으로 판단

Sheet Scaler_Graph

Sheet PPAC Efficiency
C2: Using Run 162 ~167
A3: HV | B3: 14C | C3: 16N | D3: 18O | E3: 20F
A4: 565 | B4: 0.632911 | C4: 0.870192 | D4: 0.977384 | E4: 0.998031
A5: 575 | B5: 0.812425 | C5: 0.96129 | D5: 0.994094 | E5: 0.998165
A6: 585 | B6: 0.891505 | C6: 0.990014 | D6: 0.998415 | E6: 1
A7: 595 | B7: 0.958904 | C7: 1 | D7: 0.996694 | E7: 1
A8: 600 | B8: 0.970346 | C8: 0.997904 | D8: 0.997608 | E8: 0.997375
A9: 605 | B9: 0.977413 | C9: 0.994652 | D9: 0.995283 | E9: 1
A11: Based on the events filtered by dE(SSD)-TOF(F2PP-F3PP) cut
C17: Using Runs for O20 Mom Dis.
A18: HV | B18: C | C18: N | D18: O | E18: F | F18: Ne | G18: Na
A19: 550 | B19: 0 | C19: 0 | D19: 0.823786 | E19: 0.889265 | F19: 0.943161 | G19: 0.970549
A20: 575 | B20: 0 | C20: 0 | D20: 0.943331 | E20: 0.967769 | F20: 0.978241 | G20: 0.982507
A21: 585 | B21: 0 | C21: 0.889729 | D21: 0.948202 | E21: 0.968272 | F21: 0.984033 | G21: 0.982857
A22: 595 | B22: 0.881641 | C22: 0.943014 | D22: 0.979005 | E22: 0.992705 | F22: 0.992012 | G22: 0

Sheet Beamline_Setting
D1: Attenuation | E1: Brho [Tm] | I1: Beam Dump | K1: F1 slit [mm] | O1: F2 up slit [mm] | S1: F2 down slit [mm] | W1: F3 up slit [mm] | AA1: F3 down slit [mm]
A2: Group | B2: Setting | C2: Runs | E2: D1 | F2: D2 | G2: F2F3 | H2: d/R | I2: L | J2: R | K2: xL | L2: xR | M2: yU | N2: yD | O2: xL | P2: xR | Q2: yU | R2: yD | S2: xL | T2: xR | U2: yU | V2: yD | W2: xL | X2: xR | Y2: yU | Z2: yD | AA2: xL | AB2: xR | AC2: yU | AD2: yD
A3: Cross Section | B3: 18O | C3: 251-254 | D3: -4 | E3: 1.3258 | F3: 1.304 | G3: 1.3009 | H3: 0.049 | I3: 210 | J3: 210 | K3: 190 | L3: 190 | M3: 85 | N3: 85 | O3: 45 | P3: 45 | Q3: 45 | R3: 45 | S3: 45 | T3: 45 | U3: 45 | V3: 45 | W3: 45 | X3: 45 | Y3: 45 | Z3: 45 | AA3: 45 | AB3: 45 | AC3: 45 | AD3: 45
B4: 19O | C4: 259-299 | D4: -4 | E4: 1.352 | F4: 1.331 | G4: 1.3248 | H4: 0.052 | I4: 210 | J4: 210 | K4: 190 | L4: 190 | M4: 85 | N4: 85 | O4: 45 | P4: 45 | Q4: 45 | R4: 45 | S4: 45 | T4: 45 | U4: 45 | V4: 45 | W4: 45 | X4: 45 | Y4: 45 | Z4: 45 | AA4: 45 | AB4: 45 | AC4: 45 | AD4: 45
B5: 20O | C5: 304-310 | D5: -2 | E5: 1.4092 | F5: 1.3876 | G5: 1.3812 | H5: 0.051 | I5: 210 | J5: 210 | K5: 190 | L5: 190 | M5: 85 | N5: 85 | O5: 45 | P5: 45 | Q5: 45 | R5: 45 | S5: 45 | T5: 45 | U5: 45 | V5: 45 | W5: 45 | X5: 45 | Y5: 45 | Z5: 45 | AA5: 45 | AB5: 45 | AC5: 45 | AD5: 45
B6: 21O | C6: 316-347 | D6: -2 | E6: 1.4291 | F6: 1.4045 | G6: 1.3964 | H6: 0.055 | I6: 210 | J6: 210 | K6: 190 | L6: 190 | M6: 85 | N6: 85 | O6: 45 | P6: 45 | Q6: 45 | R6: 45 | S6: 45 | T6: 45 | U6: 45 | V6: 45 | W6: 45 | X6: 45 | Y6: 45 | Z6: 45 | AA6: 45 | AB6: 45 | AC6: 45 | AD6: 45
B7: 22O | C7: 348-404 | D7: -2 | E7: 1.4969 | F7: 1.4728 | G7: 1.4662 | H7: 0.052 | I7: 210 | J7: 210 | K7: 190 | L7: 190 | M7: 85 | N7: 85 | O7: 45 | P7: 45 | Q7: 45 | R7: 45 | S7: 45 | T7: 45 | U7: 45 | V7: 45 | W7: 45 | X7: 45 | Y7: 45 | Z7: 45 | AA7: 45 | AB7: 45 | AC7: 45 | AD7: 45
B8: 24Ne | C8: 410-415 | D8: -4 | E8: 1.3076 | F8: 1.2777 | G8: 1.2677 | H8: 0.072 | I8: 210 | J8: 210 | K8: 190 | L8: 190 | M8: 85 | N8: 85 | O8: 45 | P8: 45 | Q8: 45 | R8: 45 | S8: 45 | T8: 45 | U8: 45 | V8: 45 | W8: 45 | X8: 45 | Y8: 45 | Z8: 45 | AA8: 45 | AB8: 45 | AC8: 45 | AD8: 45
B9: 25Ne | C9: 420-422 | D9: -2 | E9: 1.3655 | F9: 1.3359 | G9: 1.326 | H9: 0.069 | I9: 210 | J9: 210 | K9: 84 | L9: 80 | M9: 20 | N9: 30 | O9: 45 | P9: 45 | Q9: 45 | R9: 45 | S9: 45 | T9: 45 | U9: 45 | V9: 45 | W9: 45 | X9: 45 | Y9: 45 | Z9: 45 | AA9: 45 | AB9: 45 | AC9: 45 | AD9: 45
B10: 26Ne | C10: 425-440 | D10: -2 | E10: 1.4208 | F10: 1.3912 | G10: 1.3814 | H10: 0.066 | I10: 210 | J10: 210 | K10: 190 | L10: 190 | M10: 85 | N10: 85 | O10: 45 | P10: 45 | Q10: 45 | R10: 45 | S10: 45 | T10: 45 | U10: 45 | V10: 45 | W10: 45 | X10: 45 | Y10: 45 | Z10: 45 | AA10: 45 | AB10: 45 | AC10: 45 | AD10: 45
A11: Momentum Distribution 20O | B11: -12 | C11: 643-648 | D11: -2 | E11: 1.2384 | F11: 1.2075 | G11: 1.1971 | H11: 0.079 | I11: 210 | J11: 210 | K11: 5 | L11: 1 | M11: 85 | N11: 85 | O11: 45 | P11: 45 | Q11: 45 | R11: 45 | S11: 45 | T11: 45 | U11: 45 | V11: 45 | W11: 45 | X11: 45 | Y11: 45 | Z11: 45 | AA11: 45 | AB11: 45 | AC11: 45 | AD11: 45
B12: -10 | C12: 639-642 | D12: -2 | E12: 1.2666 | F12: 1.2374 | G12: 1.2277 | H12: 0.073 | I12: 210 | J12: 210 | K12: 6.5 | L12: 2.5 | M12: 85 | N12: 85 | O12: 45 | P12: 45 | Q12: 45 | R12: 45 | S12: 45 | T12: 45 | U12: 45 | V12: 45 | W12: 45 | X12: 45 | Y12: 45 | Z12: 45 | AA12: 45 | AB12: 45 | AC12: 45 | AD12: 45
B13: -8 | C13: 620-625 | D13: -2 | E13: 1.2947 | F13: 1.2672 | G13: 1.2581 | H13: 0.068 | I13: 210 | J13: 210 | K13: 23 | L13: 19 | M13: 85 | N13: 85 | O13: 45 | P13: 45 | Q13: 45 | R13: 45 | S13: 45 | T13: 45 | U13: 45 | V13: 45 | W13: 45 | X13: 45 | Y13: 45 | Z13: 45 | AA13: 45 | AB13: 45 | AC13: 45 | AD13: 45
B14: -7 | C14: 651-655 | D14: -2 | E14: 1.3088 | F14: 1.2821 | G14: 1.2732 | H14: 0.065 | I14: 210 | J14: 210 | K14: 35 | L14: 31 | M14: 85 | N14: 85 | O14: 45 | P14: 45 | Q14: 45 | R14: 45 | S14: 45 | T14: 45 | U14: 45 | V14: 45 | W14: 45 | X14: 45 | Y14: 45 | Z14: 45 | AA14: 45 | AB14: 45 | AC14: 45 | AD14: 45
B15: -6 | C15: 615-617 | D15: -2 | E15: 1.3229 | F15: 1.2968 | G15: 1.2882 | H15: 0.063 | I15: 210 | J15: 210 | K15: 25 | L15: 21 | M15: 85 | N15: 85 | O15: 45 | P15: 45 | Q15: 45 | R15: 45 | S15: 45 | T15: 45 | U15: 45 | V15: 45 | W15: 45 | X15: 45 | Y15: 45 | Z15: 45 | AA15: 45 | AB15: 45 | AC15: 45 | AD15: 45
B16: -5 | C16: 660-661 | D16: -2 | E16: 1.3369 | F16: 1.3116 | G16: 1.3032 | H16: 0.061 | I16: 210 | J16: 210 | K16: 55 | L16: 51 | M16: 85 | N16: 85 | O16: 45 | P16: 45 | Q16: 45 | R16: 45 | S16: 45 | T16: 45 | U16: 45 | V16: 45 | W16: 45 | X16: 45 | Y16: 45 | Z16: 45 | AA16: 45 | AB16: 45 | AC16: 45 | AD16: 45
B17: -4 | C17: 610-612 | D17: -2 | E17: 1.351 | F17: 1.3264 | G17: 1.3183 | H17: 0.059 | I17: 210 | J17: 210 | K17: 45 | L17: 41 | M17: 85 | N17: 85 | O17: 45 | P17: 45 | Q17: 45 | R17: 45 | S17: 45 | T17: 45 | U17: 45 | V17: 45 | W17: 45 | X17: 45 | Y17: 45 | Z17: 45 | AA17: 45 | AB17: 45 | AC17: 45 | AD17: 45
B18: 0 | C18: 601-604 | D18: -2 | E18: 1.4073 | F18: 1.3837 | G18: 1.3812 | H18: 0.051 | I18: 210 | J18: 210 | K18: 190 | L18: 190 | M18: 85 | N18: 85 | O18: 45 | P18: 45 | Q18: 45 | R18: 45 | S18: 45 | T18: 45 | U18: 45 | V18: 45 | W18: 45 | X18: 45 | Y18: 45 | Z18: 45 | AA18: 45 | AB18: 45 | AC18: 45 | AD18: 45
B19: 4 | C19: 605-607 | D19: -2 | E19: 1.4636 | F19: 1.4436 | G19: 1.4371 | H19: 0.045 | I19: 210 | J19: 210 | K19: 190 | L19: 190 | M19: 85 | N19: 85 | O19: 45 | P19: 45 | Q19: 45 | R19: 45 | S19: 45 | T19: 45 | U19: 45 | V19: 45 | W19: 45 | X19: 45 | Y19: 45 | Z19: 45 | AA19: 45 | AB19: 45 | AC19: 45 | AD19: 45
B20: 7 | C20: 590-598 | D20: -2 | E20: 1.5065 | F20: 1.4872 | G20: 1.4812 | H20: 0.041 | I20: 210 | J20: 210 | K20: 190 | L20: 190 | M20: 85 | N20: 85 | O20: 45 | P20: 45 | Q20: 45 | R20: 45 | S20: 45 | T20: 45 | U20: 45 | V20: 45 | W20: 45 | X20: 45 | Y20: 45 | Z20: 45 | AA20: 45 | AB20: 45 | AC20: 45 | AD20: 45
A21: Momentum Distribution 24Ne | B21: -10 | C21: 775-779 | D21: -2 | E21: 1.1768 | F21: 1.1374 | G21: 1.124 | H21: 0.101 | I21: 210 | J21: 210 | K21: 1 | L21: 0 | M21: 85 | N21: 85 | O21: 45 | P21: 45 | Q21: 45 | R21: 45 | S21: 45 | T21: 45 | U21: 45 | V21: 45 | W21: 45 | X21: 45 | Y21: 45 | Z21: 45 | AA21: 45 | AB21: 45 | AC21: 45 | AD21: 45
B22: -8 | C22: 763-765 | D22: -2 | E22: 1.203 | F22: 1.1659 | G22: 1.1534 | H22: 0.094 | I22: 210 | J22: 210 | K22: 2 | L22: 0 | M22: 85 | N22: 85 | O22: 45 | P22: 45 | Q22: 45 | R22: 45 | S22: 45 | T22: 45 | U22: 45 | V22: 45 | W22: 45 | X22: 45 | Y22: 45 | Z22: 45 | AA22: 45 | AB22: 45 | AC22: 45 | AD22: 45
B23: -7 | C23: 780-781 | D23: -2 | E23: 1.2161 | F23: 1.18 | G23: 1.1679 | H23: 0.091 | I23: 210 | J23: 210 | K23: 4 | L23: 0 | M23: 85 | N23: 85 | O23: 45 | P23: 45 | Q23: 45 | R23: 45 | S23: 45 | T23: 45 | U23: 45 | V23: 45 | W23: 45 | X23: 45 | Y23: 45 | Z23: 45 | AA23: 45 | AB23: 45 | AC23: 45 | AD23: 45
B24: -6 | C24: 754-759 | D24: -2 | E24: 1.2291 | F24: 1.194 | G24: 1.1823 | H24: 0.088 | I24: 210 | J24: 210 | K24: 4.5 | L24: 0.5 | M24: 85 | N24: 85 | O24: 45 | P24: 45 | Q24: 45 | R24: 45 | S24: 45 | T24: 45 | U24: 45 | V24: 45 | W24: 45 | X24: 45 | Y24: 45 | Z24: 45 | AA24: 45 | AB24: 45 | AC24: 45 | AD24: 45
B25: -5 | C25: 782-785 | D25: -2 | E25: 1.2422 | F25: 1.2081 | G25: 1.1966 | H25: 0.085 | I25: 210 | J25: 210 | K25: 5.5 | L25: 1.5 | M25: 85 | N25: 85 | O25: 45 | P25: 45 | Q25: 45 | R25: 45 | S25: 45 | T25: 45 | U25: 45 | V25: 45 | W25: 45 | X25: 45 | Y25: 45 | Z25: 45 | AA25: 45 | AB25: 45 | AC25: 45 | AD25: 45
B26: -4 | C26: 750-752 | D26: -2 | E26: 1.2553 | F26: 1.2221 | G26: 1.2109 | H26: 0.082 | I26: 210 | J26: 210 | K26: 6.2 | L26: 2.2 | M26: 85 | N26: 85 | O26: 45 | P26: 45 | Q26: 45 | R26: 45 | S26: 45 | T26: 45 | U26: 45 | V26: 45 | W26: 45 | X26: 45 | Y26: 45 | Z26: 45 | AA26: 45 | AB26: 45 | AC26: 45 | AD26: 45
B27: -3 | C27: 786-787 | D27: -2 | E27: 1.2684 | F27: 1.236 | G27: 1.2252 | H27: 0.079 | I27: 210 | J27: 210 | K27: 7 | L27: 3 | M27: 85 | N27: 85 | O27: 45 | P27: 45 | Q27: 45 | R27: 45 | S27: 45 | T27: 45 | U27: 45 | V27: 45 | W27: 45 | X27: 45 | Y27: 45 | Z27: 45 | AA27: 45 | AB27: 45 | AC27: 45 | AD27: 45
B28: -2 | C28: 746-748 | D28: -2 | E28: 1.2814 | F28: 1.2499 | G28: 1.2394 | H28: 0.077 | I28: 210 | J28: 210 | K28: 11 | L28: 7 | M28: 85 | N28: 85 | O28: 45 | P28: 45 | Q28: 45 | R28: 45 | S28: 45 | T28: 45 | U28: 45 | V28: 45 | W28: 45 | X28: 45 | Y28: 45 | Z28: 45 | AA28: 45 | AB28: 45 | AC28: 45 | AD28: 45
B29: -1 | C29: 738-740 | D29: -2 | E29: 1.2945 | F29: 1.2638 | G29: 1.2536 | H29: 0.074 | I29: 210 | J29: 210 | K29: 19 | L29: 15 | M29: 85 | N29: 85 | O29: 45 | P29: 45 | Q29: 45 | R29: 45 | S29: 45 | T29: 45 | U29: 45 | V29: 45 | W29: 45 | X29: 45 | Y29: 45 | Z29: 45 | AA29: 45 | AB29: 45 | AC29: 45 | AD29: 45
B30: 0 | C30: 706-708 | D30: -2 | E30: 1.3076 | F30: 1.2777 | G30: 1.2677 | H30: 0.072 | I30: 210 | J30: 210 | K30: 25 | L30: 21 | M30: 85 | N30: 85 | O30: 45 | P30: 45 | Q30: 45 | R30: 45 | S30: 45 | T30: 45 | U30: 45 | V30: 45 | W30: 45 | X30: 45 | Y30: 45 | Z30: 45 | AA30: 45 | AB30: 45 | AC30: 45 | AD30: 45
B31: 1 | C31: 713-719 | D31: -2 | E31: 1.3207 | F31: 1.2915 | G31: 1.2819 | H31: 0.07 | I31: 210 | J31: 210 | K31: 37 | L31: 33 | M31: 85 | N31: 85 | O31: 45 | P31: 45 | Q31: 45 | R31: 45 | S31: 45 | T31: 45 | U31: 45 | V31: 45 | W31: 45 | X31: 45 | Y31: 45 | Z31: 45 | AA31: 45 | AB31: 45 | AC31: 45 | AD31: 45
B32: 2 | C32: 720-725 | D32: -2 | E32: 1.3337 | F32: 1.3053 | G32: 1.2959 | H32: 0.068 | I32: 210 | J32: 210 | K32: 49 | L32: 45 | M32: 85 | N32: 85 | O32: 45 | P32: 45 | Q32: 45 | R32: 45 | S32: 45 | T32: 45 | U32: 45 | V32: 45 | W32: 45 | X32: 45 | Y32: 45 | Z32: 45 | AA32: 45 | AB32: 45 | AC32: 45 | AD32: 45
B33: 4 | C33: 726-730 | D33: -2 | E33: 1.3599 | F33: 1.3329 | G33: 1.3239 | H33: 0.063 | I33: 210 | J33: 210 | K33: 86 | L33: 82 | M33: 85 | N33: 85 | O33: 45 | P33: 45 | Q33: 45 | R33: 45 | S33: 45 | T33: 45 | U33: 45 | V33: 45 | W33: 45 | X33: 45 | Y33: 45 | Z33: 45 | AA33: 45 | AB33: 45 | AC33: 45 | AD33: 45
... B35: 10 | C35: 734-737 | D35: -2 | E35: 1.4384 | F35: 1.415 | G35: 1.4073 | H35: 0.053 | I35: 210 | J35: 210 | K35: 128 | L35: 124 | M35: 85 | N35: 85 | O35: 45 | P35: 45 | Q35: 45 | R35: 45 | S35: 45 | T35: 45 | U35: 45 | V35: 45 | W35: 45 | X35: 45 | Y35: 45 | Z35: 45 | AA35: 45 | AB35: 45 | AC35: 45 | AD35: 45

Sheet CS_PID
A1: Target | B1: Run | C1: 13C | D1: 14C | E1: 15C | F1: 16C | G1: 17C | H1: 15N | I1: 16N | J1: 17N | K1: 18N | L1: 19N | M1: 20N | N1: 17O | O1: 18O | P1: 19O | Q1: 20O | R1: 21O | S1: 22O | T1: 19F | U1: 20F | V1: 21F | W1: 22F | X1: 23F | Y1: 24F | Z1: 21Ne | AA1: 22Ne | AB1: 23Ne | AC1: 24Ne | AD1: 25Ne | AE1: 26Ne | AF1: 23Na | AG1: 24Na | AH1: 25Na | AI1: 26Na | AJ1: 27Na | AK1: 28Na | AL1: 26Mg | AM1: 27Mg | AN1: 28Mg | AO1: 29Mg | AP1: 30Mg | AQ1: 29Al | AR1: 30Al | AS1: 31Al
A2: 18O | B2: 251 | C2: 11 | D2: 40 | E2: 5 | F2: 0 | G2: 0 | H2: 14 | I2: 44 | J2: 10 | K2: 0 | L2: 0 | M2: 0 | N2: 6 | O2: 76 | P2: 11 | Q2: 1 | R2: 0 | S2: 0 | T2: 5 | U2: 37 | V2: 7 | W2: 0 | X2: 0 | Y2: 0 | Z2: 3 | AA2: 8 | AB2: 0 | AC2: 0 | AD2: 0 | AE2: 0 | AF2: 1 | AG2: 0 | AH2: 0 | AI2: 0 | AJ2: 0 | AK2: 0 | AL2: 0 | AM2: 0 | AN2: 0 | AO2: 0 | AP2: 0 | AQ2: 0 | AR2: 0 | AS2: 0
A3: 18O | B3: 252 | C3: 58 | D3: 211 | E3: 20 | F3: 1 | G3: 0 | H3: 94 | I3: 173 | J3: 78 | K3: 1 | L3: 0 | M3: 0 | N3: 42 | O3: 393 | P3: 54 | Q3: 2 | R3: 0 | S3: 0 | T3: 28 | U3: 181 | V3: 27 | W3: 0 | X3: 0 | Y3: 0 | Z3: 6 | AA3: 23 | AB3: 0 | AC3: 0 | AD3: 0 | AE3: 0 | AF3: 3 | AG3: 0 | AH3: 0 | AI3: 0 | AJ3: 0 | AK3: 0 | AL3: 0 | AM3: 0 | AN3: 0 | AO3: 0 | AP3: 0 | AQ3: 0 | AR3: 0 | AS3: 0
A4: 18O | B4: 253 | C4: 35 | D4: 122 | E4: 14 | F4: 0 | G4: 0 | H4: 56 | I4: 131 | J4: 42 | K4: 0 | L4: 0 | M4: 0 | N4: 22 | O4: 237 | P4: 38 | Q4: 0 | R4: 0 | S4: 0 | T4: 16 | U4: 123 | V4: 13 | W4: 0 | X4: 0 | Y4: 0 | Z4: 12 | AA4: 24 | AB4: 1 | AC4: 0 | AD4: 0 | AE4: 0 | AF4: 0 | AG4: 0 | AH4: 0 | AI4: 0 | AJ4: 0 | AK4: 0 | AL4: 0 | AM4: 0 | AN4: 0 | AO4: 0 | AP4: 0 | AQ4: 0 | AR4: 0 | AS4: 0
A5: 18O | B5: 254 | C5: 59 | D5: 196 | E5: 24 | F5: 0 | G5: 0 | H5: 102 | I5: 205 | J5: 72 | K5: 0 | L5: 0 | M5: 0 | N5: 31 | O5: 377 | P5: 71 | Q5: 0 | R5: 0 | S5: 0 | T5: 21 | U5: 207 | V5: 27 | W5: 0 | X5: 0 | Y5: 0 | Z5: 10 | AA5: 37 | AB5: 2 | AC5: 0 | AD5: 0 | AE5: 0 | AF5: 4 | AG5: 3 | AH5: 0 | AI5: 0 | AJ5: 0 | AK5: 0 | AL5: 0 | AM5: 0 | AN5: 0 | AO5: 0 | AP5: 0 | AQ5: 0 | AR5: 0 | AS5: 0
A6: 19O | B6: 259 | C6: 0 | D6: 15 | E6: 8 | F6: 0 | G6: 0 | H6: 2 | I6: 10 | J6: 21 | K6: 1 | L6: 0 | M6: 0 | N6: 2 | O6: 22 | P6: 45 | Q6: 7 | R6: 0 | S6: 0 | T6: 0 | U6: 39 | V6: 53 | W6: 1 | X6: 0 | Y6: 0 | Z6: 0 | AA6: 14 | AB6: 7 | AC6: 0 | AD6: 0 | AE6: 0 | AF6: 0 | AG6: 4 | AH6: 3 | AI6: 0 | AJ6: 0 | AK6: 0 | AL6: 1 | AM6: 0 | AN6: 0 | AO6: 0 | AP6: 0 | AQ6: 0 | AR6: 0 | AS6: 0
A7: 19O | B7: 260 | C7: 1 | D7: 29 | E7: 13 | F7: 1 | G7: 0 | H7: 3 | I7: 19 | J7: 52 | K7: 2 | L7: 0 | M7: 0 | N7: 0 | O7: 37 | P7: 62 | Q7: 8 | R7: 0 | S7: 0 | T7: 0 | U7: 36 | V7: 79 | W7: 4 | X7: 0 | Y7: 0 | Z7: 2 | AA7: 26 | AB7: 16 | AC7: 2 | AD7: 0 | AE7: 0 | AF7: 1 | AG7: 2 | AH7: 1 | AI7: 0 | AJ7: 0 | AK7: 0 | AL7: 1 | AM7: 0 | AN7: 0 | AO7: 0 | AP7: 0 | AQ7: 0 | AR7: 0 | AS7: 0
A8: 19O | B8: 261 | C8: 2 | D8: 41 | E8: 20 | F8: 1 | G8: 0 | H8: 3 | I8: 33 | J8: 75 | K8: 5 | L8: 0 | M8: 0 | N8: 3 | O8: 75 | P8: 101 | Q8: 13 | R8: 0 | S8: 0 | T8: 0 | U8: 68 | V8: 156 | W8: 9 | X8: 0 | Y8: 0 | Z8: 0 | AA8: 43 | AB8: 29 | AC8: 1 | AD8: 0 | AE8: 0 | AF8: 0 | AG8: 6 | AH8: 1 | AI8: 0 | AJ8: 0 | AK8: 0 | AL8: 0 | AM8: 0 | AN8: 0 | AO8: 0 | AP8: 0 | AQ8: 0 | AR8: 0 | AS8: 0
A9: 19O | B9: 262 | C9: 2 | D9: 23 | E9: 8 | F9: 2 | G9: 0 | H9: 3 | I9: 20 | J9: 24 | K9: 0 | L9: 0 | M9: 0 | N9: 2 | O9: 36 | P9: 57 | Q9: 3 | R9: 0 | S9: 0 | T9: 0 | U9: 33 | V9: 61 | W9: 4 | X9: 0 | Y9: 0 | Z9: 0 | AA9: 25 | AB9: 12 | AC9: 1 | AD9: 0 | AE9: 0 | AF9: 0 | AG9: 0 | AH9: 1 | AI9: 0 | AJ9: 0 | AK9: 0 | AL9: 0 | AM9: 0 | AN9: 0 | AO9: 0 | AP9: 0 | AQ9: 0 | AR9: 0 | AS9: 0
A10: 19O | B10: 263 | C10: 1 | D10: 25 | E10: 10 | F10: 0 | G10: 0 | H10: 1 | I10: 15 | J10: 40 | K10: 6 | L10: 1 | M10: 0 | N10: 1 | O10: 48 | P10: 44 | Q10: 5 | R10: 0 | S10: 0 | T10: 0 | U10: 20 | V10: 59 | W10: 2 | X10: 0 | Y10: 0 | Z10: 1 | AA10: 18 | AB10: 11 | AC10: 0 | AD10: 0 | AE10: 0 | AF10: 0 | AG10: 9 | AH10: 0 | AI10: 0 | AJ10: 0 | AK10: 0 | AL10: 0 | AM10: 0 | AN10: 0 | AO10: 0 | AP10: 0 | AQ10: 0 | AR10: 0 | AS10: 0
A11: 19O | B11: 264 | C11: 1 | D11: 39 | E11: 17 | F11: 0 | G11: 0 | H11: 1 | I11: 19 | J11: 55 | K11: 3 | L11: 0 | M11: 0 | N11: 2 | O11: 46 | P11: 83 | Q11: 12 | R11: 0 | S11: 0 | T11: 0 | U11: 52 | V11: 120 | W11: 3 | X11: 0 | Y11: 0 | Z11: 0 | AA11: 29 | AB11: 19 | AC11: 1 | AD11: 0 | AE11: 0 | AF11: 0 | AG11: 1 | AH11: 1 | AI11: 0 | AJ11: 0 | AK11: 0 | AL11: 0 | AM11: 0 | AN11: 0 | AO11: 0 | AP11: 0 | AQ11: 0 | AR11: 0 | AS11: 0
A12: 19O | B12: 265 | C12: 1 | D12: 12 | E12: 1 | F12: 1 | G12: 0 | H12: 2 | I12: 8 | J12: 11 | K12: 1 | L12: 0 | M12: 0 | N12: 0 | O12: 16 | P12: 17 | Q12: 3 | R12: 0 | S12: 0 | T12: 2 | U12: 16 | V12: 25 | W12: 2 | X12: 0 | Y12: 0 | Z12: 0 | AA12: 11 | AB12: 6 | AC12: 0 | AD12: 0 | AE12: 0 | AF12: 0 | AG12: 2 | AH12: 0 | AI12: 0 | AJ12: 0 | AK12: 0 | AL12: 0 | AM12: 0 | AN12: 0 | AO12: 0 | AP12: 0 | AQ12: 0 | AR12: 0 | AS12: 0
A13: 19O | B13: 266 | C13: 2 | D13: 20 | E13: 3 | F13: 1 | G13: 0 | H13: 3 | I13: 16 | J13: 34 | K13: 5 | L13: 0 | M13: 0 | N13: 1 | O13: 36 | P13: 49 | Q13: 5 | R13: 1 | S13: 0 | T13: 1 | U13: 31 | V13: 55 | W13: 3 | X13: 0 | Y13: 0 | Z13: 1 | AA13: 22 | AB13: 9 | AC13: 1 | AD13: 0 | AE13: 0 | AF13: 0 | AG13: 6 | AH13: 1 | AI13: 0 | AJ13: 0 | AK13: 0 | AL13: 1 | AM13: 0 | AN13: 0 | AO13: 0 | AP13: 0 | AQ13: 0 | AR13: 0 | AS13: 0
... A151: 26Ne | B151: 440 | C151: 0 | D151: 3 | E151: 0 | F151: 0 | G151: 0 | H151: 0 | I151: 0 | J151: 1 | K151: 0 | L151: 3 | M151: 0 | N151: 0 | O151: 0 | P151: 0 | Q151: 6 | R151: 0 | S151: 2 | T151: 0 | U151: 0 | V151: 0 | W151: 4 | X151: 8 | Y151: 4 | Z151: 0 | AA151: 0 | AB151: 0 | AC151: 4 | AD151: 6 | AE151: 3 | AF151: 0 | AG151: 0 | AH151: 0 | AI151: 0 | AJ151: 16 | AK151: 1 | AL151: 0 | AM151: 0 | AN151: 2 | AO151: 20 | AP151: 9 | AQ151: 0 | AR151: 0 | AS151: 21

Sheet CS_VS_LEBT
A1: Target | B1: Run | C1: LEBT | D1: 17O | E1: 18O | F1: 19O | H1: Target | I1: Run | J1: LEBT | K1: 18O | L1: 19O | M1: 21F | O1: Target | P1: Run | Q1: LEBT | R1: 19O | S1: 20O | T1: 21F | V1: Target | W1: Run | X1: LEBT | Y1: 20O | Z1: 22F | AA1: 23F | AC1: Target | AD1: Run | AE1: LEBT | AF1: 17O | AG1: 18O | AH1: 19O | AJ1: Target | AK1: Run | AL1: LEBT | AM1: 17O | AN1: 18O | AO1: 19O | AQ1: Target | AR1: Run | AS1: LEBT | AT1: 17O | AU1: 18O | AV1: 19O | AX1: Target | AY1: Run | AZ1: LEBT | BA1: 17O | BB1: 18O | BC1: 19O
A2: 18O | B2: 251 | C2: =VLOOKUP(B2,LEBT[#ALL],4) -> 3.5642886e-05 | D2: =VLOOKUP($B2,CS_PID!$B$1:$AS$151,MATCH(D$1,CS_PID!$B$1:$AS$1,0), FALSE) -> 6 | E2: =VLOOKUP($B2,CS_PID!$B$1:$AS$151,MATCH(E$1,CS_PID!$B$1:$AS$1,0), FALSE) -> 76 | F2: =VLOOKUP($B2,CS_PID!$B$1:$AS$151,MATCH(F$1,CS_PID!$B$1:$AS$1,0), FALSE) -> 11 | H2: 19O | I2: 259 | J2: =VLOOKUP(I2,LEBT[#ALL],4) -> 3.9883044e-05 | K2: =VLOOKUP($I2,CS_PID!$B$1:$AS$151,MATCH(K$1,CS_PID!$B$1:$AS$1,0), FALSE) -> 22 | L2: =VLOOKUP($I2,CS_PID!$B$1:$AS$151,MATCH(L$1,CS_PID!$B$1:$AS$1,0), FALSE) -> 45 | M2: =VLOOKUP($I2,CS_PID!$B$1:$AS$151,MATCH(M$1,CS_PID!$B$1:$AS$1,0), FALSE) -> 53 | O2: 20O | P2: 304 | Q2: =VLOOKUP(P2,LEBT[#ALL],4) -> 3.7104984e-05 | R2: =VLOOKUP($P2,CS_PID!$B$1:$AS$151,MATCH(R$1,CS_PID!$B$1:$AS$1,0), FALSE) -> 592 | S2: =VLOOKUP($P2,CS_PID!$B$1:$AS$151,MATCH(S$1,CS_PID!$B$1:$AS$1,0), FALSE) -> 527 | T2: =VLOOKUP($P2,CS_PID!$B$1:$AS$151,MATCH(T$1,CS_PID!$B$1:$AS$1,0), FALSE) -> 613 | V2: 21O | W2: 316 | X2: =VLOOKUP(W2,LEBT[#ALL],4) -> 4.1023598e-05 | Y2: =VLOOKUP($W2,CS_PID!$B$1:$AS$151,MATCH(Y$1,CS_PID!$B$1:$AS$1,0), FALSE) -> 134 | Z2: =VLOOKUP($W2,CS_PID!$B$1:$AS$151,MATCH(Z$1,CS_PID!$B$1:$AS$1,0), FALSE) -> 111 | AA2: =VLOOKUP($W2,CS_PID!$B$1:$AS$151,MATCH(AA$1,CS_PID!$B$1:$AS$1,0), FALSE) -> 71 | AC2: 22O | AD2: 223 | AE2: =VLOOKUP(AD2,LEBT[#ALL],4) -> 3.5446938e-05 | AF2: =VLOOKUP($AD2,CS_PID!$B$1:$AS$151,MATCH(AF$1,CS_PID!$B$1:$AS$1, 0), FALSE) -> 0 | AG2: =VLOOKUP($AD2,CS_PID!$B$1:$AS$151,MATCH(AG$1,CS_PID!$B$1:$AS$1, 0), FALSE) -> 0 | AH2: =VLOOKUP($AD2,CS_PID!$B$1:$AS$151,MATCH(AH$1,CS_PID!$B$1:$AS$1, 0), FALSE) -> 0 | AJ2: 24Ne | AK2: 410 | AL2: =VLOOKUP(AK2,LEBT[#ALL],4) -> 3.5879559e-05 | AM2: =VLOOKUP($AK2,CS_PID!$B$1:$AS$151,MATCH(AM$1,CS_PID!$B$1:$AS$1,0), FALSE) -> 0 | AN2: =VLOOKUP($AK2,CS_PID!$B$1:$AS$151,MATCH(AN$1,CS_PID!$B$1:$AS$1,0), FALSE) -> 1 | AO2: =VLOOKUP($AK2,CS_PID!$B$1:$AS$151,MATCH(AO$1,CS_PID!$B$1:$AS$1,0), FALSE) -> 0 | AQ2: 25Ne | AR2: 420 | AS2: =VLOOKUP(AR2,LEBT[#ALL],4) -> 3.9515415e-05 | AT2: =VLOOKUP($AR2,CS_PID!$B$1:$AS$151,MATCH(AT$1,CS_PID!$B$1:$AS$1,0), FALSE) -> 0 | AU2: =VLOOKUP($AR2,CS_PID!$B$1:$AS$151,MATCH(AU$1,CS_PID!$B$1:$AS$1,0), FALSE) -> 0 | AV2: =VLOOKUP($AR2,CS_PID!$B$1:$AS$151,MATCH(AV$1,CS_PID!$B$1:$AS$1,0), FALSE) -> 0 | AX2: 26Ne | AY2: 425 | AZ2: =VLOOKUP(AY2,LEBT[#ALL],4) -> 3.974559e-05 | BA2: =VLOOKUP($AY2,CS_PID!$B$1:$AS$151,MATCH(BA$1,CS_PID!$B$1:$AS$1, 0), FALSE) -> 0 | BB2: =VLOOKUP($AY2,CS_PID!$B$1:$AS$151,MATCH(BB$1,CS_PID!$B$1:$AS$1,0), FALSE) -> 1 | BC2: =VLOOKUP($AY2,CS_PID!$B$1:$AS$151,MATCH(BC$1,CS_PID!$B$1:$AS$1,0), FALSE) -> 0
A3: 18O | B3: 252 | C3: =VLOOKUP(B3,LEBT[#ALL],4) -> 3.6338045e-05 | D3: =VLOOKUP($B3,CS_PID!$B$1:$AS$151,MATCH(D$1,CS_PID!$B$1:$AS$1,0), FALSE) -> 42 | E3: =VLOOKUP($B3,CS_PID!$B$1:$AS$151,MATCH(E$1,CS_PID!$B$1:$AS$1,0), FALSE) -> 393 | F3: =VLOOKUP($B3,CS_PID!$B$1:$AS$151,MATCH(F$1,CS_PID!$B$1:$AS$1,0), FALSE) -> 54 | H3: 19O | I3: 260 | J3: =VLOOKUP(I3,LEBT[#ALL],4) -> 4.0107395e-05 | K3: =VLOOKUP($I3,CS_PID!$B$1:$AS$151,MATCH(K$1,CS_PID!$B$1:$AS$1,0), FALSE) -> 37 | L3: =VLOOKUP($I3,CS_PID!$B$1:$AS$151,MATCH(L$1,CS_PID!$B$1:$AS$1,0), FALSE) -> 62 | M3: =VLOOKUP($I3,CS_PID!$B$1:$AS$151,MATCH(M$1,CS_PID!$B$1:$AS$1,0), FALSE) -> 79 | O3: 20O | P3: 305 | Q3: =VLOOKUP(P3,LEBT[#ALL],4) -> 4.1347376e-05 | R3: =VLOOKUP($P3,CS_PID!$B$1:$AS$151,MATCH(R$1,CS_PID!$B$1:$AS$1,0), FALSE) -> 1193 | S3: =VLOOKUP($P3,CS_PID!$B$1:$AS$151,MATCH(S$1,CS_PID!$B$1:$AS$1,0), FALSE) -> 1059 | T3: =VLOOKUP($P3,CS_PID!$B$1:$AS$151,MATCH(T$1,CS_PID!$B$1:$AS$1,0), FALSE) -> 1218 | V3: 21O | W3: 318 | X3: =VLOOKUP(W3,LEBT[#ALL],4) -> 4.1294202e-05 | Y3: =VLOOKUP($W3,CS_PID!$B$1:$AS$151,MATCH(Y$1,CS_PID!$B$1:$AS$1,0), FALSE) -> 179 | Z3: =VLOOKUP($W3,CS_PID!$B$1:$AS$151,MATCH(Z$1,CS_PID!$B$1:$AS$1,0), FALSE) -> 194 | AA3: =VLOOKUP($W3,CS_PID!$B$1:$AS$151,MATCH(AA$1,CS_PID!$B$1:$AS$1,0), FALSE) -> 116 | AC3: 22O | AD3: 224 | AE3: =VLOOKUP(AD3,LEBT[#ALL],4) -> 3.6488055e-05 | AF3: =VLOOKUP($AD3,CS_PID!$B$1:$AS$151,MATCH(AF$1,CS_PID!$B$1:$AS$1, 0), FALSE) -> 0 | AG3: =VLOOKUP($AD3,CS_PID!$B$1:$AS$151,MATCH(AG$1,CS_PID!$B$1:$AS$1, 0), FALSE) -> 0 | AH3: =VLOOKUP($AD3,CS_PID!$B$1:$AS$151,MATCH(AH$1,CS_PID!$B$1:$AS$1, 0), FALSE) -> 0 | AJ3: 24Ne | AK3: 411 | AL3: =VLOOKUP(AK3,LEBT[#ALL],4) -> 4.0087141e-05 | AM3: =VLOOKUP($AK3,CS_PID!$B$1:$AS$151,MATCH(AM$1,CS_PID!$B$1:$AS$1,0), FALSE) -> 0 | AN3: =VLOOKUP($AK3,CS_PID!$B$1:$AS$151,MATCH(AN$1,CS_PID!$B$1:$AS$1,0), FALSE) -> 0 | AO3: =VLOOKUP($AK3,CS_PID!$B$1:$AS$151,MATCH(AO$1,CS_PID!$B$1:$AS$1,0), FALSE) -> 2 | AQ3: 25Ne | AR3: 421 | AS3: =VLOOKUP(AR3,LEBT[#ALL],4) -> 4.0517218e-05 | AT3: =VLOOKUP($AR3,CS_PID!$B$1:$AS$151,MATCH(AT$1,CS_PID!$B$1:$AS$1,0), FALSE) -> 0 | AU3: =VLOOKUP($AR3,CS_PID!$B$1:$AS$151,MATCH(AU$1,CS_PID!$B$1:$AS$1,0), FALSE) -> 0 | AV3: =VLOOKUP($AR3,CS_PID!$B$1:$AS$151,MATCH(AV$1,CS_PID!$B$1:$AS$1,0), FALSE) -> 7 | AX3: 26Ne | AY3: 426 | AZ3: =VLOOKUP(AY3,LEBT[#ALL],4) -> 4.0049335e-05 | BA3: =VLOOKUP($AY3,CS_PID!$B$1:$AS$151,MATCH(BA$1,CS_PID!$B$1:$AS$1, 0), FALSE) -> 0 | BB3: =VLOOKUP($AY3,CS_PID!$B$1:$AS$151,MATCH(BB$1,CS_PID!$B$1:$AS$1,0), FALSE) -> 0 | BC3: =VLOOKUP($AY3,CS_PID!$B$1:$AS$151,MATCH(BC$1,CS_PID!$B$1:$AS$1,0), FALSE) -> 2
A4: 18O | B4: 253 | C4: =VLOOKUP(B4,LEBT[#ALL],4) -> 3.602189e-05 | D4: =VLOOKUP($B4,CS_PID!$B$1:$AS$151,MATCH(D$1,CS_PID!$B$1:$AS$1,0), FALSE) -> 22 | E4: =VLOOKUP($B4,CS_PID!$B$1:$AS$151,MATCH(E$1,CS_PID!$B$1:$AS$1,0), FALSE) -> 237 | F4: =VLOOKUP($B4,CS_PID!$B$1:$AS$151,MATCH(F$1,CS_PID!$B$1:$AS$1,0), FALSE) -> 38 | H4: 19O | I4: 261 | J4: =VLOOKUP(I4,LEBT[#ALL],4) -> 4.0226632e-05 | K4: =VLOOKUP($I4,CS_PID!$B$1:$AS$151,MATCH(K$1,CS_PID!$B$1:$AS$1,0), FALSE) -> 75 | L4: =VLOOKUP($I4,CS_PID!$B$1:$AS$151,MATCH(L$1,CS_PID!$B$1:$AS$1,0), FALSE) -> 101 | M4: =VLOOKUP($I4,CS_PID!$B$1:$AS$151,MATCH(M$1,CS_PID!$B$1:$AS$1,0), FALSE) -> 156 | O4: 20O | P4: 306 | Q4: =VLOOKUP(P4,LEBT[#ALL],4) -> 4.0992575e-05 | R4: =VLOOKUP($P4,CS_PID!$B$1:$AS$151,MATCH(R$1,CS_PID!$B$1:$AS$1,0), FALSE) -> 1076 | S4: =VLOOKUP($P4,CS_PID!$B$1:$AS$151,MATCH(S$1,CS_PID!$B$1:$AS$1,0), FALSE) -> 866 | T4: =VLOOKUP($P4,CS_PID!$B$1:$AS$151,MATCH(T$1,CS_PID!$B$1:$AS$1,0), FALSE) -> 1120 | V4: 21O | W4: 319 | X4: =VLOOKUP(W4,LEBT[#ALL],4) -> 3.8226606e-05 | Y4: =VLOOKUP($W4,CS_PID!$B$1:$AS$151,MATCH(Y$1,CS_PID!$B$1:$AS$1,0), FALSE) -> 14 | Z4: =VLOOKUP($W4,CS_PID!$B$1:$AS$151,MATCH(Z$1,CS_PID!$B$1:$AS$1,0), FALSE) -> 14 | AA4: =VLOOKUP($W4,CS_PID!$B$1:$AS$151,MATCH(AA$1,CS_PID!$B$1:$AS$1,0), FALSE) -> 6 | AC4: 22O | AD4: 225 | AE4: =VLOOKUP(AD4,LEBT[#ALL],4) -> 3.3200448e-05 | AF4: =VLOOKUP($AD4,CS_PID!$B$1:$AS$151,MATCH(AF$1,CS_PID!$B$1:$AS$1, 0), FALSE) -> 0 | AG4: =VLOOKUP($AD4,CS_PID!$B$1:$AS$151,MATCH(AG$1,CS_PID!$B$1:$AS$1, 0), FALSE) -> 0 | AH4: =VLOOKUP($AD4,CS_PID!$B$1:$AS$151,MATCH(AH$1,CS_PID!$B$1:$AS$1, 0), FALSE) -> 0 | AJ4: 24Ne | AK4: 412 | AL4: =VLOOKUP(AK4,LEBT[#ALL],4) -> 4.0844403e-05 | AM4: =VLOOKUP($AK4,CS_PID!$B$1:$AS$151,MATCH(AM$1,CS_PID!$B$1:$AS$1,0), FALSE) -> 0 | AN4: =VLOOKUP($AK4,CS_PID!$B$1:$AS$151,MATCH(AN$1,CS_PID!$B$1:$AS$1,0), FALSE) -> 2 | AO4: =VLOOKUP($AK4,CS_PID!$B$1:$AS$151,MATCH(AO$1,CS_PID!$B$1:$AS$1,0), FALSE) -> 4 | AQ4: 25Ne | AR4: 422 | AS4: =VLOOKUP(AR4,LEBT[#ALL],4) -> 4.0444702e-05 | AT4: =VLOOKUP($AR4,CS_PID!$B$1:$AS$151,MATCH(AT$1,CS_PID!$B$1:$AS$1,0), FALSE) -> 0 | AU4: =VLOOKUP($AR4,CS_PID!$B$1:$AS$151,MATCH(AU$1,CS_PID!$B$1:$AS$1,0), FALSE) -> 0 | AV4: =VLOOKUP($AR4,CS_PID!$B$1:$AS$151,MATCH(AV$1,CS_PID!$B$1:$AS$1,0), FALSE) -> 8 | AX4: 26Ne | AY4: 427 | AZ4: =VLOOKUP(AY4,LEBT[#ALL],4) -> 4.0023211e-05 | BA4: =VLOOKUP($AY4,CS_PID!$B$1:$AS$151,MATCH(BA$1,CS_PID!$B$1:$AS$1, 0), FALSE) -> 0 | BB4: =VLOOKUP($AY4,CS_PID!$B$1:$AS$151,MATCH(BB$1,CS_PID!$B$1:$AS$1,0), FALSE) -> 1 | BC4: =VLOOKUP($AY4,CS_PID!$B$1:$AS$151,MATCH(BC$1,CS_PID!$B$1:$AS$1,0), FALSE) -> 0
A5: 18O | B5: 254 | C5: =VLOOKUP(B5,LEBT[#ALL],4) -> 4.079048e-05 | D5: =VLOOKUP($B5,CS_PID!$B$1:$AS$151,MATCH(D$1,CS_PID!$B$1:$AS$1,0), FALSE) -> 31 | E5: =VLOOKUP($B5,CS_PID!$B$1:$AS$151,MATCH(E$1,CS_PID!$B$1:$AS$1,0), FALSE) -> 377 | F5: =VLOOKUP($B5,CS_PID!$B$1:$AS$151,MATCH(F$1,CS_PID!$B$1:$AS$1,0), FALSE) -> 71 | H5: 19O | I5: 262 | J5: =VLOOKUP(I5,LEBT[#ALL],4) -> 3.9870625e-05 | K5: =VLOOKUP($I5,CS_PID!$B$1:$AS$151,MATCH(K$1,CS_PID!$B$1:$AS$1,0), FALSE) -> 36 | L5: =VLOOKUP($I5,CS_PID!$B$1:$AS$151,MATCH(L$1,CS_PID!$B$1:$AS$1,0), FALSE) -> 57 | M5: =VLOOKUP($I5,CS_PID!$B$1:$AS$151,MATCH(M$1,CS_PID!$B$1:$AS$1,0), FALSE) -> 61 | O5: 20O | P5: 307 | Q5: =VLOOKUP(P5,LEBT[#ALL],4) -> 3.9154276e-05 | R5: =VLOOKUP($P5,CS_PID!$B$1:$AS$151,MATCH(R$1,CS_PID!$B$1:$AS$1,0), FALSE) -> 130 | S5: =VLOOKUP($P5,CS_PID!$B$1:$AS$151,MATCH(S$1,CS_PID!$B$1:$AS$1,0), FALSE) -> 107 | T5: =VLOOKUP($P5,CS_PID!$B$1:$AS$151,MATCH(T$1,CS_PID!$B$1:$AS$1,0), FALSE) -> 137 | V5: 21O | W5: 320 | X5: =VLOOKUP(W5,LEBT[#ALL],4) -> 4.1086807e-05 | Y5: =VLOOKUP($W5,CS_PID!$B$1:$AS$151,MATCH(Y$1,CS_PID!$B$1:$AS$1,0), FALSE) -> 126 | Z5: =VLOOKUP($W5,CS_PID!$B$1:$AS$151,MATCH(Z$1,CS_PID!$B$1:$AS$1,0), FALSE) -> 89 | AA5: =VLOOKUP($W5,CS_PID!$B$1:$AS$151,MATCH(AA$1,CS_PID!$B$1:$AS$1,0), FALSE) -> 66 | AC5: 22O | AD5: 226 | AE5: =VLOOKUP(AD5,LEBT[#ALL],4) -> 3.7032915e-05 | AF5: =VLOOKUP($AD5,CS_PID!$B$1:$AS$151,MATCH(AF$1,CS_PID!$B$1:$AS$1, 0), FALSE) -> 0 | AG5: =VLOOKUP($AD5,CS_PID!$B$1:$AS$151,MATCH(AG$1,CS_PID!$B$1:$AS$1, 0), FALSE) -> 0 | AH5: =VLOOKUP($AD5,CS_PID!$B$1:$AS$151,MATCH(AH$1,CS_PID!$B$1:$AS$1, 0), FALSE) -> 0 | AJ5: 24Ne | AK5: 413 | AL5: =VLOOKUP(AK5,LEBT[#ALL],4) -> 4.0845804e-05 | AM5: =VLOOKUP($AK5,CS_PID!$B$1:$AS$151,MATCH(AM$1,CS_PID!$B$1:$AS$1,0), FALSE) -> 0 | AN5: =VLOOKUP($AK5,CS_PID!$B$1:$AS$151,MATCH(AN$1,CS_PID!$B$1:$AS$1,0), FALSE) -> 0 | AO5: =VLOOKUP($AK5,CS_PID!$B$1:$AS$151,MATCH(AO$1,CS_PID!$B$1:$AS$1,0), FALSE) -> 3 | AX5: 26Ne | AY5: 428 | AZ5: =VLOOKUP(AY5,LEBT[#ALL],4) -> 4.0205941e-05 | BA5: =VLOOKUP($AY5,CS_PID!$B$1:$AS$151,MATCH(BA$1,CS_PID!$B$1:$AS$1, 0), FALSE) -> 0 | BB5: =VLOOKUP($AY5,CS_PID!$B$1:$AS$151,MATCH(BB$1,CS_PID!$B$1:$AS$1,0), FALSE) -> 0 | BC5: =VLOOKUP($AY5,CS_PID!$B$1:$AS$151,MATCH(BC$1,CS_PID!$B$1:$AS$1,0), FALSE) -> 2
H6: 19O | I6: 263 | J6: =VLOOKUP(I6,LEBT[#ALL],4) -> 3.9844319e-05 | K6: =VLOOKUP($I6,CS_PID!$B$1:$AS$151,MATCH(K$1,CS_PID!$B$1:$AS$1,0), FALSE) -> 48 | L6: =VLOOKUP($I6,CS_PID!$B$1:$AS$151,MATCH(L$1,CS_PID!$B$1:$AS$1,0), FALSE) -> 44 | M6: =VLOOKUP($I6,CS_PID!$B$1:$AS$151,MATCH(M$1,CS_PID!$B$1:$AS$1,0), FALSE) -> 59 | O6: 20O | P6: 308 | Q6: =VLOOKUP(P6,LEBT[#ALL],4) -> 3.7956757e-05 | R6: =VLOOKUP($P6,CS_PID!$B$1:$AS$151,MATCH(R$1,CS_PID!$B$1:$AS$1,0), FALSE) -> 68 | S6: =VLOOKUP($P6,CS_PID!$B$1:$AS$151,MATCH(S$1,CS_PID!$B$1:$AS$1,0), FALSE) -> 61 | T6: =VLOOKUP($P6,CS_PID!$B$1:$AS$151,MATCH(T$1,CS_PID!$B$1:$AS$1,0), FALSE) -> 69 | V6: 21O | W6: 321 | X6: =VLOOKUP(W6,LEBT[#ALL],4) -> 4.0575936e-05 | Y6: =VLOOKUP($W6,CS_PID!$B$1:$AS$151,MATCH(Y$1,CS_PID!$B$1:$AS$1,0), FALSE) -> 55 | Z6: =VLOOKUP($W6,CS_PID!$B$1:$AS$151,MATCH(Z$1,CS_PID!$B$1:$AS$1,0), FALSE) -> 61 | AA6: =VLOOKUP($W6,CS_PID!$B$1:$AS$151,MATCH(AA$1,CS_PID!$B$1:$AS$1,0), FALSE) -> 37 | AC6: 22O | AD6: 348 | AE6: =VLOOKUP(AD6,LEBT[#ALL],4) -> 3.6342221e-05 | AF6: =VLOOKUP($AD6,CS_PID!$B$1:$AS$151,MATCH(AF$1,CS_PID!$B$1:$AS$1, 0), FALSE) -> 0 | AG6: =VLOOKUP($AD6,CS_PID!$B$1:$AS$151,MATCH(AG$1,CS_PID!$B$1:$AS$1, 0), FALSE) -> 0 | AH6: =VLOOKUP($AD6,CS_PID!$B$1:$AS$151,MATCH(AH$1,CS_PID!$B$1:$AS$1, 0), FALSE) -> 0 | AJ6: 24Ne | AK6: 415 | AL6: =VLOOKUP(AK6,LEBT[#ALL],4) -> 4.0118268e-05 | AM6: =VLOOKUP($AK6,CS_PID!$B$1:$AS$151,MATCH(AM$1,CS_PID!$B$1:$AS$1,0), FALSE) -> 0 | AN6: =VLOOKUP($AK6,CS_PID!$B$1:$AS$151,MATCH(AN$1,CS_PID!$B$1:$AS$1,0), FALSE) -> 0 | AO6: =VLOOKUP($AK6,CS_PID!$B$1:$AS$151,MATCH(AO$1,CS_PID!$B$1:$AS$1,0), FALSE) -> 0 | AX6: 26Ne | AY6: 429 | AZ6: =VLOOKUP(AY6,LEBT[#ALL],4) -> 4.0793794e-05 | BA6: =VLOOKUP($AY6,CS_PID!$B$1:$AS$151,MATCH(BA$1,CS_PID!$B$1:$AS$1, 0), FALSE) -> 0 | BB6: =VLOOKUP($AY6,CS_PID!$B$1:$AS$151,MATCH(BB$1,CS_PID!$B$1:$AS$1,0), FALSE) -> 0 | BC6: =VLOOKUP($AY6,CS_PID!$B$1:$AS$151,MATCH(BC$1,CS_PID!$B$1:$AS$1,0), FALSE) -> 2
H7: 19O | I7: 264 | J7: =VLOOKUP(I7,LEBT[#ALL],4) -> 4.0125177e-05 | K7: =VLOOKUP($I7,CS_PID!$B$1:$AS$151,MATCH(K$1,CS_PID!$B$1:$AS$1,0), FALSE) -> 46 | L7: =VLOOKUP($I7,CS_PID!$B$1:$AS$151,MATCH(L$1,CS_PID!$B$1:$AS$1,0), FALSE) -> 83 | M7: =VLOOKUP($I7,CS_PID!$B$1:$AS$151,MATCH(M$1,CS_PID!$B$1:$AS$1,0), FALSE) -> 120 | O7: 20O | P7: 309 | Q7: =VLOOKUP(P7,LEBT[#ALL],4) -> 4.0022025e-05 | R7: =VLOOKUP($P7,CS_PID!$B$1:$AS$151,MATCH(R$1,CS_PID!$B$1:$AS$1,0), FALSE) -> 256 | S7: =VLOOKUP($P7,CS_PID!$B$1:$AS$151,MATCH(S$1,CS_PID!$B$1:$AS$1,0), FALSE) -> 202 | T7: =VLOOKUP($P7,CS_PID!$B$1:$AS$151,MATCH(T$1,CS_PID!$B$1:$AS$1,0), FALSE) -> 255 | V7: 21O | W7: 322 | X7: =VLOOKUP(W7,LEBT[#ALL],4) -> 4.0670815e-05 | Y7: =VLOOKUP($W7,CS_PID!$B$1:$AS$151,MATCH(Y$1,CS_PID!$B$1:$AS$1,0), FALSE) -> 75 | Z7: =VLOOKUP($W7,CS_PID!$B$1:$AS$151,MATCH(Z$1,CS_PID!$B$1:$AS$1,0), FALSE) -> 81 | AA7: =VLOOKUP($W7,CS_PID!$B$1:$AS$151,MATCH(AA$1,CS_PID!$B$1:$AS$1,0), FALSE) -> 50 | AC7: 22O | AD7: 349 | AE7: =VLOOKUP(AD7,LEBT[#ALL],4) -> 3.6065466e-05 | AF7: =VLOOKUP($AD7,CS_PID!$B$1:$AS$151,MATCH(AF$1,CS_PID!$B$1:$AS$1, 0), FALSE) -> 0 | AG7: =VLOOKUP($AD7,CS_PID!$B$1:$AS$151,MATCH(AG$1,CS_PID!$B$1:$AS$1, 0), FALSE) -> 0 | AH7: =VLOOKUP($AD7,CS_PID!$B$1:$AS$151,MATCH(AH$1,CS_PID!$B$1:$AS$1, 0), FALSE) -> 2 | AX7: 26Ne | AY7: 430 | AZ7: =VLOOKUP(AY7,LEBT[#ALL],4) -> 4.0561214e-05 | BA7: =VLOOKUP($AY7,CS_PID!$B$1:$AS$151,MATCH(BA$1,CS_PID!$B$1:$AS$1, 0), FALSE) -> 0 | BB7: =VLOOKUP($AY7,CS_PID!$B$1:$AS$151,MATCH(BB$1,CS_PID!$B$1:$AS$1,0), FALSE) -> 0 | BC7: =VLOOKUP($AY7,CS_PID!$B$1:$AS$151,MATCH(BC$1,CS_PID!$B$1:$AS$1,0), FALSE) -> 0
H8: 19O | I8: 265 | J8: =VLOOKUP(I8,LEBT[#ALL],4) -> 3.8988165e-05 | K8: =VLOOKUP($I8,CS_PID!$B$1:$AS$151,MATCH(K$1,CS_PID!$B$1:$AS$1,0), FALSE) -> 16 | L8: =VLOOKUP($I8,CS_PID!$B$1:$AS$151,MATCH(L$1,CS_PID!$B$1:$AS$1,0), FALSE) -> 17 | M8: =VLOOKUP($I8,CS_PID!$B$1:$AS$151,MATCH(M$1,CS_PID!$B$1:$AS$1,0), FALSE) -> 25 | O8: 20O | P8: 310 | Q8: =VLOOKUP(P8,LEBT[#ALL],4) -> 4.0704527e-05 | R8: =VLOOKUP($P8,CS_PID!$B$1:$AS$151,MATCH(R$1,CS_PID!$B$1:$AS$1,0), FALSE) -> 354 | S8: =VLOOKUP($P8,CS_PID!$B$1:$AS$151,MATCH(S$1,CS_PID!$B$1:$AS$1,0), FALSE) -> 289 | T8: =VLOOKUP($P8,CS_PID!$B$1:$AS$151,MATCH(T$1,CS_PID!$B$1:$AS$1,0), FALSE) -> 391 | V8: 21O | W8: 323 | X8: =VLOOKUP(W8,LEBT[#ALL],4) -> 3.8966682e-05 | Y8: =VLOOKUP($W8,CS_PID!$B$1:$AS$151,MATCH(Y$1,CS_PID!$B$1:$AS$1,0), FALSE) -> 58 | Z8: =VLOOKUP($W8,CS_PID!$B$1:$AS$151,MATCH(Z$1,CS_PID!$B$1:$AS$1,0), FALSE) -> 62 | AA8: =VLOOKUP($W8,CS_PID!$B$1:$AS$151,MATCH(AA$1,CS_PID!$B$1:$AS$1,0), FALSE) -> 27 | AC8: 22O | AD8: 350 | AE8: =VLOOKUP(AD8,LEBT[#ALL],4) -> 3.6756402e-05 | AF8: =VLOOKUP($AD8,CS_PID!$B$1:$AS$151,MATCH(AF$1,CS_PID!$B$1:$AS$1, 0), FALSE) -> 0 | AG8: =VLOOKUP($AD8,CS_PID!$B$1:$AS$151,MATCH(AG$1,CS_PID!$B$1:$AS$1, 0), FALSE) -> 0 | AH8: =VLOOKUP($AD8,CS_PID!$B$1:$AS$151,MATCH(AH$1,CS_PID!$B$1:$AS$1, 0), FALSE) -> 0 | AX8: 26Ne | AY8: 431 | AZ8: =VLOOKUP(AY8,LEBT[#ALL],4) -> 4.027562e-05 | BA8: =VLOOKUP($AY8,CS_PID!$B$1:$AS$151,MATCH(BA$1,CS_PID!$B$1:$AS$1, 0), FALSE) -> 0 | BB8: =VLOOKUP($AY8,CS_PID!$B$1:$AS$151,MATCH(BB$1,CS_PID!$B$1:$AS$1,0), FALSE) -> 0 | BC8: =VLOOKUP($AY8,CS_PID!$B$1:$AS$151,MATCH(BC$1,CS_PID!$B$1:$AS$1,0), FALSE) -> 2
H9: 19O | I9: 266 | J9: =VLOOKUP(I9,LEBT[#ALL],4) -> 3.9709556e-05 | K9: =VLOOKUP($I9,CS_PID!$B$1:$AS$151,MATCH(K$1,CS_PID!$B$1:$AS$1,0), FALSE) -> 36 | L9: =VLOOKUP($I9,CS_PID!$B$1:$AS$151,MATCH(L$1,CS_PID!$B$1:$AS$1,0), FALSE) -> 49 | M9: =VLOOKUP($I9,CS_PID!$B$1:$AS$151,MATCH(M$1,CS_PID!$B$1:$AS$1,0), FALSE) -> 55 | V9: 21O | W9: 324 | X9: =VLOOKUP(W9,LEBT[#ALL],4) -> 3.8834212e-05 | Y9: =VLOOKUP($W9,CS_PID!$B$1:$AS$151,MATCH(Y$1,CS_PID!$B$1:$AS$1,0), FALSE) -> 51 | Z9: =VLOOKUP($W9,CS_PID!$B$1:$AS$151,MATCH(Z$1,CS_PID!$B$1:$AS$1,0), FALSE) -> 50 | AA9: =VLOOKUP($W9,CS_PID!$B$1:$AS$151,MATCH(AA$1,CS_PID!$B$1:$AS$1,0), FALSE) -> 26 | AC9: 22O | AD9: 351 | AE9: =VLOOKUP(AD9,LEBT[#ALL],4) -> 3.3353712e-05 | AF9: =VLOOKUP($AD9,CS_PID!$B$1:$AS$151,MATCH(AF$1,CS_PID!$B$1:$AS$1, 0), FALSE) -> 0 | AG9: =VLOOKUP($AD9,CS_PID!$B$1:$AS$151,MATCH(AG$1,CS_PID!$B$1:$AS$1, 0), FALSE) -> 0 | AH9: =VLOOKUP($AD9,CS_PID!$B$1:$AS$151,MATCH(AH$1,CS_PID!$B$1:$AS$1, 0), FALSE) -> 0 | AX9: 26Ne | AY9: 433 | AZ9: =VLOOKUP(AY9,LEBT[#ALL],4) -> 4.1890855e-05 | BA9: =VLOOKUP($AY9,CS_PID!$B$1:$AS$151,MATCH(BA$1,CS_PID!$B$1:$AS$1, 0), FALSE) -> 0 | BB9: =VLOOKUP($AY9,CS_PID!$B$1:$AS$151,MATCH(BB$1,CS_PID!$B$1:$AS$1,0), FALSE) -> 0 | BC9: =VLOOKUP($AY9,CS_PID!$B$1:$AS$151,MATCH(BC$1,CS_PID!$B$1:$AS$1,0), FALSE) -> 0
H10: 19O | I10: 267 | J10: =VLOOKUP(I10,LEBT[#ALL],4) -> 3.9310383e-05 | K10: =VLOOKUP($I10,CS_PID!$B$1:$AS$151,MATCH(K$1,CS_PID!$B$1:$AS$1,0), FALSE) -> 46 | L10: =VLOOKUP($I10,CS_PID!$B$1:$AS$151,MATCH(L$1,CS_PID!$B$1:$AS$1,0), FALSE) -> 76 | M10: =VLOOKUP($I10,CS_PID!$B$1:$AS$151,MATCH(M$1,CS_PID!$B$1:$AS$1,0), FALSE) -> 76 | V10: 21O | W10: 325 | X10: =VLOOKUP(W10,LEBT[#ALL],4) -> 3.6884373e-05 | Y10: =VLOOKUP($W10,CS_PID!$B$1:$AS$151,MATCH(Y$1,CS_PID!$B$1:$AS$1,0), FALSE) -> 17 | Z10: =VLOOKUP($W10,CS_PID!$B$1:$AS$151,MATCH(Z$1,CS_PID!$B$1:$AS$1,0), FALSE) -> 15 | AA10: =VLOOKUP($W10,CS_PID!$B$1:$AS$151,MATCH(AA$1,CS_PID!$B$1:$AS$1,0), FALSE) -> 7 | AC10: 22O | AD10: 352 | AE10: =VLOOKUP(AD10,LEBT[#ALL],4) -> 3.6695569e-05 | AF10: =VLOOKUP($AD10,CS_PID!$B$1:$AS$151,MATCH(AF$1,CS_PID!$B$1:$AS$1, 0), FALSE) -> 0 | AG10: =VLOOKUP($AD10,CS_PID!$B$1:$AS$151,MATCH(AG$1,CS_PID!$B$1:$AS$1, 0), FALSE) -> 0 | AH10: =VLOOKUP($AD10,CS_PID!$B$1:$AS$151,MATCH(AH$1,CS_PID!$B$1:$AS$1, 0), FALSE) -> 1 | AX10: 26Ne | AY10: 434 | AZ10: =VLOOKUP(AY10,LEBT[#ALL],4) -> 4.1209778e-05 | BA10: =VLOOKUP($AY10,CS_PID!$B$1:$AS$151,MATCH(BA$1,CS_PID!$B$1:$AS$1, 0), FALSE) -> 0 | BB10: =VLOOKUP($AY10,CS_PID!$B$1:$AS$151,MATCH(BB$1,CS_PID!$B$1:$AS$1,0), FALSE) -> 1 | BC10: =VLOOKUP($AY10,CS_PID!$B$1:$AS$151,MATCH(BC$1,CS_PID!$B$1:$AS$1,0), FALSE) -> 0
H11: 19O | I11: 271 | J11: =VLOOKUP(I11,LEBT[#ALL],4) -> 3.8893587e-05 | K11: =VLOOKUP($I11,CS_PID!$B$1:$AS$151,MATCH(K$1,CS_PID!$B$1:$AS$1,0), FALSE) -> 22 | L11: =VLOOKUP($I11,CS_PID!$B$1:$AS$151,MATCH(L$1,CS_PID!$B$1:$AS$1,0), FALSE) -> 25 | M11: =VLOOKUP($I11,CS_PID!$B$1:$AS$151,MATCH(M$1,CS_PID!$B$1:$AS$1,0), FALSE) -> 29 | V11: 21O | W11: 326 | X11: =VLOOKUP(W11,LEBT[#ALL],4) -> 3.9008553e-05 | Y11: =VLOOKUP($W11,CS_PID!$B$1:$AS$151,MATCH(Y$1,CS_PID!$B$1:$AS$1,0), FALSE) -> 73 | Z11: =VLOOKUP($W11,CS_PID!$B$1:$AS$151,MATCH(Z$1,CS_PID!$B$1:$AS$1,0), FALSE) -> 59 | AA11: =VLOOKUP($W11,CS_PID!$B$1:$AS$151,MATCH(AA$1,CS_PID!$B$1:$AS$1,0), FALSE) -> 27 | AC11: 22O | AD11: 361 | AE11: =VLOOKUP(AD11,LEBT[#ALL],4) -> 3.68731e-05 | AF11: =VLOOKUP($AD11,CS_PID!$B$1:$AS$151,MATCH(AF$1,CS_PID!$B$1:$AS$1, 0), FALSE) -> 0 | AG11: =VLOOKUP($AD11,CS_PID!$B$1:$AS$151,MATCH(AG$1,CS_PID!$B$1:$AS$1, 0), FALSE) -> 0 | AH11: =VLOOKUP($AD11,CS_PID!$B$1:$AS$151,MATCH(AH$1,CS_PID!$B$1:$AS$1, 0), FALSE) -> 0 | AX11: 26Ne | AY11: 435 | AZ11: =VLOOKUP(AY11,LEBT[#ALL],4) -> 4.115931e-05 | BA11: =VLOOKUP($AY11,CS_PID!$B$1:$AS$151,MATCH(BA$1,CS_PID!$B$1:$AS$1, 0), FALSE) -> 0 | BB11: =VLOOKUP($AY11,CS_PID!$B$1:$AS$151,MATCH(BB$1,CS_PID!$B$1:$AS$1,0), FALSE) -> 0 | BC11: =VLOOKUP($AY11,CS_PID!$B$1:$AS$151,MATCH(BC$1,CS_PID!$B$1:$AS$1,0), FALSE) -> 0
H12: 19O | I12: 272 | J12: =VLOOKUP(I12,LEBT[#ALL],4) -> 3.7818205e-05 | K12: =VLOOKUP($I12,CS_PID!$B$1:$AS$151,MATCH(K$1,CS_PID!$B$1:$AS$1,0), FALSE) -> 7 | L12: =VLOOKUP($I12,CS_PID!$B$1:$AS$151,MATCH(L$1,CS_PID!$B$1:$AS$1,0), FALSE) -> 15 | M12: =VLOOKUP($I12,CS_PID!$B$1:$AS$151,MATCH(M$1,CS_PID!$B$1:$AS$1,0), FALSE) -> 18 | V12: 21O | W12: 327 | X12: =VLOOKUP(W12,LEBT[#ALL],4) -> 3.9129965e-05 | Y12: =VLOOKUP($W12,CS_PID!$B$1:$AS$151,MATCH(Y$1,CS_PID!$B$1:$AS$1,0), FALSE) -> 117 | Z12: =VLOOKUP($W12,CS_PID!$B$1:$AS$151,MATCH(Z$1,CS_PID!$B$1:$AS$1,0), FALSE) -> 93 | AA12: =VLOOKUP($W12,CS_PID!$B$1:$AS$151,MATCH(AA$1,CS_PID!$B$1:$AS$1,0), FALSE) -> 48 | AC12: 22O | AD12: 362 | AE12: =VLOOKUP(AD12,LEBT[#ALL],4) -> 3.6520579e-05 | AF12: =VLOOKUP($AD12,CS_PID!$B$1:$AS$151,MATCH(AF$1,CS_PID!$B$1:$AS$1, 0), FALSE) -> 0 | AG12: =VLOOKUP($AD12,CS_PID!$B$1:$AS$151,MATCH(AG$1,CS_PID!$B$1:$AS$1, 0), FALSE) -> 0 | AH12: =VLOOKUP($AD12,CS_PID!$B$1:$AS$151,MATCH(AH$1,CS_PID!$B$1:$AS$1, 0), FALSE) -> 0 | AX12: 26Ne | AY12: 436 | AZ12: =VLOOKUP(AY12,LEBT[#ALL],4) -> 3.6836939e-05 | BA12: =VLOOKUP($AY12,CS_PID!$B$1:$AS$151,MATCH(BA$1,CS_PID!$B$1:$AS$1, 0), FALSE) -> 0 | BB12: =VLOOKUP($AY12,CS_PID!$B$1:$AS$151,MATCH(BB$1,CS_PID!$B$1:$AS$1,0), FALSE) -> 0 | BC12: =VLOOKUP($AY12,CS_PID!$B$1:$AS$151,MATCH(BC$1,CS_PID!$B$1:$AS$1,0), FALSE) -> 0
H13: 19O | I13: 273 | J13: =VLOOKUP(I13,LEBT[#ALL],4) -> 3.7370776e-05 | K13: =VLOOKUP($I13,CS_PID!$B$1:$AS$151,MATCH(K$1,CS_PID!$B$1:$AS$1,0), FALSE) -> 5 | L13: =VLOOKUP($I13,CS_PID!$B$1:$AS$151,MATCH(L$1,CS_PID!$B$1:$AS$1,0), FALSE) -> 17 | M13: =VLOOKUP($I13,CS_PID!$B$1:$AS$151,MATCH(M$1,CS_PID!$B$1:$AS$1,0), FALSE) -> 15 | V13: 21O | W13: 328 | X13: =VLOOKUP(W13,LEBT[#ALL],4) -> 3.9434679e-05 | Y13: =VLOOKUP($W13,CS_PID!$B$1:$AS$151,MATCH(Y$1,CS_PID!$B$1:$AS$1,0), FALSE) -> 167 | Z13: =VLOOKUP($W13,CS_PID!$B$1:$AS$151,MATCH(Z$1,CS_PID!$B$1:$AS$1,0), FALSE) -> 148 | AA13: =VLOOKUP($W13,CS_PID!$B$1:$AS$151,MATCH(AA$1,CS_PID!$B$1:$AS$1,0), FALSE) -> 74 | AC13: 22O | AD13: 364 | AE13: =VLOOKUP(AD13,LEBT[#ALL],4) -> 3.8893884e-05 | AF13: =VLOOKUP($AD13,CS_PID!$B$1:$AS$151,MATCH(AF$1,CS_PID!$B$1:$AS$1, 0), FALSE) -> 0 | AG13: =VLOOKUP($AD13,CS_PID!$B$1:$AS$151,MATCH(AG$1,CS_PID!$B$1:$AS$1, 0), FALSE) -> 0 | AH13: =VLOOKUP($AD13,CS_PID!$B$1:$AS$151,MATCH(AH$1,CS_PID!$B$1:$AS$1, 0), FALSE) -> 0 | AX13: 26Ne | AY13: 437 | AZ13: =VLOOKUP(AY13,LEBT[#ALL],4) -> 4.111572e-05 | BA13: =VLOOKUP($AY13,CS_PID!$B$1:$AS$151,MATCH(BA$1,CS_PID!$B$1:$AS$1, 0), FALSE) -> 0 | BB13: =VLOOKUP($AY13,CS_PID!$B$1:$AS$151,MATCH(BB$1,CS_PID!$B$1:$AS$1,0), FALSE) -> 0 | BC13: =VLOOKUP($AY13,CS_PID!$B$1:$AS$151,MATCH(BC$1,CS_PID!$B$1:$AS$1,0), FALSE) -> 0
H14: 19O | I14: 274 | J14: =VLOOKUP(I14,LEBT[#ALL],4) -> 3.819184e-05 | K14: =VLOOKUP($I14,CS_PID!$B$1:$AS$151,MATCH(K$1,CS_PID!$B$1:$AS$1,0), FALSE) -> 18 | L14: =VLOOKUP($I14,CS_PID!$B$1:$AS$151,MATCH(L$1,CS_PID!$B$1:$AS$1,0), FALSE) -> 23 | M14: =VLOOKUP($I14,CS_PID!$B$1:$AS$151,MATCH(M$1,CS_PID!$B$1:$AS$1,0), FALSE) -> 20 | V14: 21O | W14: 329 | X14: =VLOOKUP(W14,LEBT[#ALL],4) -> 3.9412158e-05 | Y14: =VLOOKUP($W14,CS_PID!$B$1:$AS$151,MATCH(Y$1,CS_PID!$B$1:$AS$1,0), FALSE) -> 177 | Z14: =VLOOKUP($W14,CS_PID!$B$1:$AS$151,MATCH(Z$1,CS_PID!$B$1:$AS$1,0), FALSE) -> 147 | AA14: =VLOOKUP($W14,CS_PID!$B$1:$AS$151,MATCH(AA$1,CS_PID!$B$1:$AS$1,0), FALSE) -> 78 | AC14: 22O | AD14: 365 | AE14: =VLOOKUP(AD14,LEBT[#ALL],4) -> 3.8685778e-05 | AF14: =VLOOKUP($AD14,CS_PID!$B$1:$AS$151,MATCH(AF$1,CS_PID!$B$1:$AS$1, 0), FALSE) -> 0 | AG14: =VLOOKUP($AD14,CS_PID!$B$1:$AS$151,MATCH(AG$1,CS_PID!$B$1:$AS$1, 0), FALSE) -> 0 | AH14: =VLOOKUP($AD14,CS_PID!$B$1:$AS$151,MATCH(AH$1,CS_PID!$B$1:$AS$1, 0), FALSE) -> 1 | AX14: 26Ne | AY14: 438 | AZ14: =VLOOKUP(AY14,LEBT[#ALL],4) -> 4.1388107e-05 | BA14: =VLOOKUP($AY14,CS_PID!$B$1:$AS$151,MATCH(BA$1,CS_PID!$B$1:$AS$1, 0), FALSE) -> 0 | BB14: =VLOOKUP($AY14,CS_PID!$B$1:$AS$151,MATCH(BB$1,CS_PID!$B$1:$AS$1,0), FALSE) -> 0 | BC14: =VLOOKUP($AY14,CS_PID!$B$1:$AS$151,MATCH(BC$1,CS_PID!$B$1:$AS$1,0), FALSE) -> 1
H15: 19O | I15: 275 | J15: =VLOOKUP(I15,LEBT[#ALL],4) -> 3.8652708e-05 | K15: =VLOOKUP($I15,CS_PID!$B$1:$AS$151,MATCH(K$1,CS_PID!$B$1:$AS$1,0), FALSE) -> 34 | L15: =VLOOKUP($I15,CS_PID!$B$1:$AS$151,MATCH(L$1,CS_PID!$B$1:$AS$1,0), FALSE) -> 34 | M15: =VLOOKUP($I15,CS_PID!$B$1:$AS$151,MATCH(M$1,CS_PID!$B$1:$AS$1,0), FALSE) -> 36 | V15: 21O | W15: 330 | X15: =VLOOKUP(W15,LEBT[#ALL],4) -> 3.8873462e-05 | Y15: =VLOOKUP($W15,CS_PID!$B$1:$AS$151,MATCH(Y$1,CS_PID!$B$1:$AS$1,0), FALSE) -> 76 | Z15: =VLOOKUP($W15,CS_PID!$B$1:$AS$151,MATCH(Z$1,CS_PID!$B$1:$AS$1,0), FALSE) -> 50 | AA15: =VLOOKUP($W15,CS_PID!$B$1:$AS$151,MATCH(AA$1,CS_PID!$B$1:$AS$1,0), FALSE) -> 29 | AC15: 22O | AD15: 366 | AE15: =VLOOKUP(AD15,LEBT[#ALL],4) -> 3.9359325e-05 | AF15: =VLOOKUP($AD15,CS_PID!$B$1:$AS$151,MATCH(AF$1,CS_PID!$B$1:$AS$1, 0), FALSE) -> 0 | AG15: =VLOOKUP($AD15,CS_PID!$B$1:$AS$151,MATCH(AG$1,CS_PID!$B$1:$AS$1, 0), FALSE) -> 0 | AH15: =VLOOKUP($AD15,CS_PID!$B$1:$AS$151,MATCH(AH$1,CS_PID!$B$1:$AS$1, 0), FALSE) -> 1 | AX15: 26Ne | AY15: 439 | AZ15: =VLOOKUP(AY15,LEBT[#ALL],4) -> 4.0959812e-05 | BA15: =VLOOKUP($AY15,CS_PID!$B$1:$AS$151,MATCH(BA$1,CS_PID!$B$1:$AS$1, 0), FALSE) -> 0 | BB15: =VLOOKUP($AY15,CS_PID!$B$1:$AS$151,MATCH(BB$1,CS_PID!$B$1:$AS$1,0), FALSE) -> 0 | BC15: =VLOOKUP($AY15,CS_PID!$B$1:$AS$151,MATCH(BC$1,CS_PID!$B$1:$AS$1,0), FALSE) -> 0
H16: 19O | I16: 276 | J16: =VLOOKUP(I16,LEBT[#ALL],4) -> 3.8860526e-05 | K16: =VLOOKUP($I16,CS_PID!$B$1:$AS$151,MATCH(K$1,CS_PID!$B$1:$AS$1,0), FALSE) -> 44 | L16: =VLOOKUP($I16,CS_PID!$B$1:$AS$151,MATCH(L$1,CS_PID!$B$1:$AS$1,0), FALSE) -> 62 | M16: =VLOOKUP($I16,CS_PID!$B$1:$AS$151,MATCH(M$1,CS_PID!$B$1:$AS$1,0), FALSE) -> 65 | V16: 21O | W16: 331 | X16: =VLOOKUP(W16,LEBT[#ALL],4) -> 3.9203378e-05 | Y16: =VLOOKUP($W16,CS_PID!$B$1:$AS$151,MATCH(Y$1,CS_PID!$B$1:$AS$1,0), FALSE) -> 437 | Z16: =VLOOKUP($W16,CS_PID!$B$1:$AS$151,MATCH(Z$1,CS_PID!$B$1:$AS$1,0), FALSE) -> 382 | AA16: =VLOOKUP($W16,CS_PID!$B$1:$AS$151,MATCH(AA$1,CS_PID!$B$1:$AS$1,0), FALSE) -> 226 | AC16: 22O | AD16: 367 | AE16: =VLOOKUP(AD16,LEBT[#ALL],4) -> 3.8937005e-05 | AF16: =VLOOKUP($AD16,CS_PID!$B$1:$AS$151,MATCH(AF$1,CS_PID!$B$1:$AS$1, 0), FALSE) -> 0 | AG16: =VLOOKUP($AD16,CS_PID!$B$1:$AS$151,MATCH(AG$1,CS_PID!$B$1:$AS$1, 0), FALSE) -> 0 | AH16: =VLOOKUP($AD16,CS_PID!$B$1:$AS$151,MATCH(AH$1,CS_PID!$B$1:$AS$1, 0), FALSE) -> 0 | AX16: 26Ne | AY16: 440 | AZ16: =VLOOKUP(AY16,LEBT[#ALL],4) -> 4.0733378e-05 | BA16: =VLOOKUP($AY16,CS_PID!$B$1:$AS$151,MATCH(BA$1,CS_PID!$B$1:$AS$1, 0), FALSE) -> 0 | BB16: =VLOOKUP($AY16,CS_PID!$B$1:$AS$151,MATCH(BB$1,CS_PID!$B$1:$AS$1,0), FALSE) -> 0 | BC16: =VLOOKUP($AY16,CS_PID!$B$1:$AS$151,MATCH(BC$1,CS_PID!$B$1:$AS$1,0), FALSE) -> 0
H17: 19O | I17: 277 | J17: =VLOOKUP(I17,LEBT[#ALL],4) -> 3.8321942e-05 | K17: =VLOOKUP($I17,CS_PID!$B$1:$AS$151,MATCH(K$1,CS_PID!$B$1:$AS$1,0), FALSE) -> 18 | L17: =VLOOKUP($I17,CS_PID!$B$1:$AS$151,MATCH(L$1,CS_PID!$B$1:$AS$1,0), FALSE) -> 40 | M17: =VLOOKUP($I17,CS_PID!$B$1:$AS$151,MATCH(M$1,CS_PID!$B$1:$AS$1,0), FALSE) -> 47 | V17: 21O | W17: 332 | X17: =VLOOKUP(W17,LEBT[#ALL],4) -> 3.9114846e-05 | Y17: =VLOOKUP($W17,CS_PID!$B$1:$AS$151,MATCH(Y$1,CS_PID!$B$1:$AS$1,0), FALSE) -> 32 | Z17: =VLOOKUP($W17,CS_PID!$B$1:$AS$151,MATCH(Z$1,CS_PID!$B$1:$AS$1,0), FALSE) -> 40 | AA17: =VLOOKUP($W17,CS_PID!$B$1:$AS$151,MATCH(AA$1,CS_PID!$B$1:$AS$1,0), FALSE) -> 13 | AC17: 22O | AD17: 368 | AE17: =VLOOKUP(AD17,LEBT[#ALL],4) -> 3.9425638e-05 | AF17: =VLOOKUP($AD17,CS_PID!$B$1:$AS$151,MATCH(AF$1,CS_PID!$B$1:$AS$1, 0), FALSE) -> 0 | AG17: =VLOOKUP($AD17,CS_PID!$B$1:$AS$151,MATCH(AG$1,CS_PID!$B$1:$AS$1, 0), FALSE) -> 0 | AH17: =VLOOKUP($AD17,CS_PID!$B$1:$AS$151,MATCH(AH$1,CS_PID!$B$1:$AS$1, 0), FALSE) -> 2
H18: 19O | I18: 278 | J18: =VLOOKUP(I18,LEBT[#ALL],4) -> 3.8428061e-05 | K18: =VLOOKUP($I18,CS_PID!$B$1:$AS$151,MATCH(K$1,CS_PID!$B$1:$AS$1,0), FALSE) -> 42 | L18: =VLOOKUP($I18,CS_PID!$B$1:$AS$151,MATCH(L$1,CS_PID!$B$1:$AS$1,0), FALSE) -> 54 | M18: =VLOOKUP($I18,CS_PID!$B$1:$AS$151,MATCH(M$1,CS_PID!$B$1:$AS$1,0), FALSE) -> 57 | V18: 21O | W18: 333 | X18: =VLOOKUP(W18,LEBT[#ALL],4) -> 3.8329663e-05 | Y18: =VLOOKUP($W18,CS_PID!$B$1:$AS$151,MATCH(Y$1,CS_PID!$B$1:$AS$1,0), FALSE) -> 122 | Z18: =VLOOKUP($W18,CS_PID!$B$1:$AS$151,MATCH(Z$1,CS_PID!$B$1:$AS$1,0), FALSE) -> 130 | AA18: =VLOOKUP($W18,CS_PID!$B$1:$AS$151,MATCH(AA$1,CS_PID!$B$1:$AS$1,0), FALSE) -> 63 | AC18: 22O | AD18: 369 | AE18: =VLOOKUP(AD18,LEBT[#ALL],4) -> 3.5570716e-05 | AF18: =VLOOKUP($AD18,CS_PID!$B$1:$AS$151,MATCH(AF$1,CS_PID!$B$1:$AS$1, 0), FALSE) -> 0 | AG18: =VLOOKUP($AD18,CS_PID!$B$1:$AS$151,MATCH(AG$1,CS_PID!$B$1:$AS$1, 0), FALSE) -> 0 | AH18: =VLOOKUP($AD18,CS_PID!$B$1:$AS$151,MATCH(AH$1,CS_PID!$B$1:$AS$1, 0), FALSE) -> 0
H19: 19O | I19: 279 | J19: =VLOOKUP(I19,LEBT[#ALL],4) -> 3.6680755e-05 | K19: =VLOOKUP($I19,CS_PID!$B$1:$AS$151,MATCH(K$1,CS_PID!$B$1:$AS$1,0), FALSE) -> 9 | L19: =VLOOKUP($I19,CS_PID!$B$1:$AS$151,MATCH(L$1,CS_PID!$B$1:$AS$1,0), FALSE) -> 12 | M19: =VLOOKUP($I19,CS_PID!$B$1:$AS$151,MATCH(M$1,CS_PID!$B$1:$AS$1,0), FALSE) -> 21 | V19: 21O | W19: 334 | X19: =VLOOKUP(W19,LEBT[#ALL],4) -> 3.8025668e-05 | Y19: =VLOOKUP($W19,CS_PID!$B$1:$AS$151,MATCH(Y$1,CS_PID!$B$1:$AS$1,0), FALSE) -> 102 | Z19: =VLOOKUP($W19,CS_PID!$B$1:$AS$151,MATCH(Z$1,CS_PID!$B$1:$AS$1,0), FALSE) -> 71 | AA19: =VLOOKUP($W19,CS_PID!$B$1:$AS$151,MATCH(AA$1,CS_PID!$B$1:$AS$1,0), FALSE) -> 41 | AC19: 22O | AD19: 370 | AE19: =VLOOKUP(AD19,LEBT[#ALL],4) -> 3.3805099e-05 | AF19: =VLOOKUP($AD19,CS_PID!$B$1:$AS$151,MATCH(AF$1,CS_PID!$B$1:$AS$1, 0), FALSE) -> 0 | AG19: =VLOOKUP($AD19,CS_PID!$B$1:$AS$151,MATCH(AG$1,CS_PID!$B$1:$AS$1, 0), FALSE) -> 0 | AH19: =VLOOKUP($AD19,CS_PID!$B$1:$AS$151,MATCH(AH$1,CS_PID!$B$1:$AS$1, 0), FALSE) -> 0
H20: 19O | I20: 280 | J20: =VLOOKUP(I20,LEBT[#ALL],4) -> 3.683284e-05 | K20: =VLOOKUP($I20,CS_PID!$B$1:$AS$151,MATCH(K$1,CS_PID!$B$1:$AS$1,0), FALSE) -> 11 | L20: =VLOOKUP($I20,CS_PID!$B$1:$AS$151,MATCH(L$1,CS_PID!$B$1:$AS$1,0), FALSE) -> 17 | M20: =VLOOKUP($I20,CS_PID!$B$1:$AS$151,MATCH(M$1,CS_PID!$B$1:$AS$1,0), FALSE) -> 15 | V20: 21O | W20: 335 | X20: =VLOOKUP(W20,LEBT[#ALL],4) -> 3.8127964e-05 | Y20: =VLOOKUP($W20,CS_PID!$B$1:$AS$151,MATCH(Y$1,CS_PID!$B$1:$AS$1,0), FALSE) -> 148 | Z20: =VLOOKUP($W20,CS_PID!$B$1:$AS$151,MATCH(Z$1,CS_PID!$B$1:$AS$1,0), FALSE) -> 134 | AA20: =VLOOKUP($W20,CS_PID!$B$1:$AS$151,MATCH(AA$1,CS_PID!$B$1:$AS$1,0), FALSE) -> 79 | AC20: 22O | AD20: 371 | AE20: =VLOOKUP(AD20,LEBT[#ALL],4) -> 3.6635408e-05 | AF20: =VLOOKUP($AD20,CS_PID!$B$1:$AS$151,MATCH(AF$1,CS_PID!$B$1:$AS$1, 0), FALSE) -> 0 | AG20: =VLOOKUP($AD20,CS_PID!$B$1:$AS$151,MATCH(AG$1,CS_PID!$B$1:$AS$1, 0), FALSE) -> 0 | AH20: =VLOOKUP($AD20,CS_PID!$B$1:$AS$151,MATCH(AH$1,CS_PID!$B$1:$AS$1, 0), FALSE) -> 0
